Workbook

Sheet 0828
A1: 가나다란 08/28(목밤) 주문서 | I1: 발주 | L1: 장끼 | O1: 입고 | P1: 차이
A2: 거래처명 | B2: 공급처주소 | C2: 공급처연락처 | D2: 공급처휴대전화 | E2: 상품코드 | F2: 공급처상품명 | G2: 공급처옵션 | H2: 원가 | I2: 신규주문 | J2: 미송 | K2: 교환 | L2: 장끼 | M2: 미송 | N2: 교환 | O2: 주문 | P2: 주문 | Q2: 삼촌 코멘트 | R2: 가나다란 코멘트 | S2: 실입고수 | T2: 오늘입금할금액 | U2: 미송/매입금액 | V2: 입금일 | W2: 공급처예금주
I3: =SUM(I4:I335) -> 991 | J3: =SUM(J4:J335) -> 322 | K3: =SUM(K4:K335) -> 50 | L3: 647 | M3: 310 | N3: 6 | O3: =SUM(O4:O335) -> 0 | P3: =SUM(P4:P335) -> 0 | Q3: =SUM(Q4:Q335) -> 0 | R3: =SUM(R4:R335) -> 0 | S3: =SUM(S4:S335) -> 0 | T3: =SUM(T4:T335) -> 5040700 | U3: =SUM(U4:U335) -> 6107500
Q4: ※ 주문서 작성시 KDG, 제이와이엠, 디피프로젝트 카톡 채널 공유 필수 | S4: =O4 -> 0 | T4: =H4*L4 -> 0 | W4: =IFERROR(VLOOKUP(A4,거래처!B:Z,21,0),"")
A5: 썸 | B5: 본사반출 | F5: 시스루BL | G5: 검정 | R5: 08/26 본사반출 | S5: 0 | T5: 0 | W5: =IFERROR(VLOOKUP(A5,거래처!B:Z,21,0),"") -> 홍성복
S6: =O6 -> 0 | T6: =H6*L6 -> 0 | W6: =IFERROR(VLOOKUP(A6,거래처!B:Z,21,0),"")
A7: 리마인드 | B7: 경기도 고양시 일산동구 지영로 59-2 D동 | C7: 010-3918-2418 | D7: 010-9208-6514 | E7: S16809 | F7: 2420(부츠)sl (C) | G7: 베이지(기본M) | H7: 12000 | I7: 1 | L7: 1 | S7: =O7 -> 0 | T7: =H7*L7 -> 12000 | W7: =IFERROR(VLOOKUP(A7,거래처!B:Z,21,0),"") -> （주）디투어패럴
A8: 리마인드 | B8: 경기도 고양시 일산동구 지영로 59-2 D동 | C8: 010-3918-2418 | D8: 010-9208-6514 | E8: S16808 | F8: 2420(부츠)sl (C) | G8: 베이지(기본S) | H8: 12000 | I8: 1 | L8: 1 | S8: =O8 -> 0 | T8: =H8*L8 -> 12000 | W8: =IFERROR(VLOOKUP(A8,거래처!B:Z,21,0),"") -> （주）디투어패럴
A9: 리마인드 | B9: 경기도 고양시 일산동구 지영로 59-2 D동 | C9: 010-3918-2418 | D9: 010-9208-6514 | E9: S16838 | F9: 2420(부츠)sl (C) | G9: 블랙(롱S) | H9: 12000 | I9: 1 | L9: 1 | S9: =O9 -> 0 | T9: =H9*L9 -> 12000 | W9: =IFERROR(VLOOKUP(A9,거래처!B:Z,21,0),"") -> （주）디투어패럴
A10: 리마인드 | B10: 경기도 고양시 일산동구 지영로 59-2 D동 | C10: 010-3918-2418 | D10: 010-9208-6514 | E10: S16833 | F10: 2420(부츠)sl (C) | G10: 블랙(숏M) | H10: 12000 | I10: 1 | L10: 1 | S10: =O10 -> 0 | T10: =H10*L10 -> 12000 | W10: =IFERROR(VLOOKUP(A10,거래처!B:Z,21,0),"") -> （주）디투어패럴
A11: 리마인드 | B11: 경기도 고양시 일산동구 지영로 59-2 D동 | C11: 010-3918-2418 | D11: 010-9208-6514 | E11: S16800 | F11: 2420(부츠)sl (C) | G11: 아이보리(기본M) | H11: 12000 | I11: 1 | L11: 1 | S11: =O11 -> 0 | T11: =H11*L11 -> 12000 | W11: =IFERROR(VLOOKUP(A11,거래처!B:Z,21,0),"") -> （주）디투어패럴
A12: 리마인드 | B12: 경기도 고양시 일산동구 지영로 59-2 D동 | C12: 010-3918-2418 | D12: 010-9208-6514 | E12: S16796 | F12: 2420(부츠)sl (C) | G12: 아이보리(숏S) | H12: 12000 | I12: 1 | L12: 1 | S12: =O12 -> 0 | T12: =H12*L12 -> 12000 | W12: =IFERROR(VLOOKUP(A12,거래처!B:Z,21,0),"") -> （주）디투어패럴
A13: 리마인드 | B13: 경기도 고양시 일산동구 지영로 59-2 D동 | C13: 010-3918-2418 | D13: 010-9208-6514 | E13: S16823 | F13: 2420(부츠)sl (C) | G13: 회색(숏S) | H13: 12000 | I13: 1 | L13: 1 | S13: =O13 -> 0 | T13: =H13*L13 -> 12000 | W13: =IFERROR(VLOOKUP(A13,거래처!B:Z,21,0),"") -> （주）디투어패럴
A14: 리마인드 | B14: 경기도 고양시 일산동구 지영로 59-2 D동 | C14: 010-3918-2418 | D14: 010-9208-6514 | E14: S16864 | F14: 2430(와이드)sl ☆ | G14: 블랙(기본M) ☆2506 | H14: 12000 | I14: 1 | L14: 1 | S14: =O14 -> 0 | T14: =H14*L14 -> 12000 | W14: =IFERROR(VLOOKUP(A14,거래처!B:Z,21,0),"") -> （주）디투어패럴
A15: 리마인드 | B15: 경기도 고양시 일산동구 지영로 59-2 D동 | C15: 010-3918-2418 | D15: 010-9208-6514 | E15: S22138 | F15: 4503 [반바지] | G15: 블랙/L | H15: 10000 | I15: 1 | L15: 1 | S15: =O15 -> 0 | T15: =H15*L15 -> 10000 | W15: =IFERROR(VLOOKUP(A15,거래처!B:Z,21,0),"") -> （주）디투어패럴
A16: 리마인드 | B16: 경기도 고양시 일산동구 지영로 59-2 D동 | C16: 010-3918-2418 | D16: 010-9208-6514 | E16: S22132 | F16: 4503 [반바지] | G16: 아이보리/L | H16: 10000 | I16: 1 | L16: 1 | S16: =O16 -> 0 | T16: =H16*L16 -> 10000 | W16: =IFERROR(VLOOKUP(A16,거래처!B:Z,21,0),"") -> （주）디투어패럴
A17: 리마인드 | B17: 경기도 고양시 일산동구 지영로 59-2 D동 | C17: 010-3918-2418 | D17: 010-9208-6514 | E17: S22130 | F17: 4503 [반바지] | G17: 아이보리/S | H17: 10000 | I17: 5 | L17: 5 | S17: =O17 -> 0 | T17: =H17*L17 -> 50000 | W17: =IFERROR(VLOOKUP(A17,거래처!B:Z,21,0),"") -> （주）디투어패럴
A18: 리마인드 | B18: 경기도 고양시 일산동구 지영로 59-2 D동 | C18: 010-3918-2418 | D18: 010-9208-6514 | E18: S18813 | F18: 5007pt [부츠컷] | G18: 중청(M) | H18: 15000 | I18: 1 | L18: 1 | S18: =O18 -> 0 | T18: =H18*L18 -> 15000 | W18: =IFERROR(VLOOKUP(A18,거래처!B:Z,21,0),"") -> （주）디투어패럴
... A21: 리마인드 | B21: 경기도 고양시 일산동구 지영로 59-2 D동 | C21: 010-3918-2418 | D21: 010-9208-6514 | E21: S23477 | F21: 5409nt [반팔] | G21: 화이트 | H21: 9000 | I21: 3 | L21: 3 | S21: =O21 -> 0 | T21: =H21*L21 -> 27000 | W21: =IFERROR(VLOOKUP(A21,거래처!B:Z,21,0),"") -> （주）디투어패럴
A22: 리마인드 | B22: 경기도 고양시 일산동구 지영로 59-2 D동 | C22: 010-3918-2418 | D22: 010-9208-6514 | E22: S16811 | F22: 2420(부츠)sl (C) | G22: 베이지(롱S) | H22: 12000 | K22: 1 | R22: 8/21 더안불량(오염) | S22: =O22 -> 0 | T22: =H22*L22 -> 0 | W22: =IFERROR(VLOOKUP(A22,거래처!B:Z,21,0),"") -> （주）디투어패럴
A23: 리마인드 | B23: 경기도 고양시 일산동구 지영로 59-2 D동 | C23: 010-3918-2418 | D23: 010-9208-6514 | E23: S16800 | F23: 2420(부츠)sl (C) | G23: 아이보리(기본M) | H23: 12000 | K23: 1 | R23: 8/13 더안불량(오염) | S23: =O23 -> 0 | T23: =H23*L23 -> 0 | W23: =IFERROR(VLOOKUP(A23,거래처!B:Z,21,0),"") -> （주）디투어패럴
A24: 리마인드 | B24: 경기도 고양시 일산동구 지영로 59-2 D동 | C24: 010-3918-2418 | D24: 010-9208-6514 | E24: S16796 | F24: 2420(부츠)sl (C) | G24: 아이보리(숏S) | H24: 12000 | K24: 1 | R24: 8/21 더안불량(오염) | S24: =O24 -> 0 | T24: =H24*L24 -> 0 | W24: =IFERROR(VLOOKUP(A24,거래처!B:Z,21,0),"") -> （주）디투어패럴
A25: 리마인드 | B25: 경기도 고양시 일산동구 지영로 59-2 D동 | C25: 010-3918-2418 | D25: 010-9208-6514 | E25: S22136 | F25: 4503 [반바지] | G25: 블랙/S | H25: 10000 | K25: 1 | R25: 8/18 더안불량(양쪽길이 다름) | S25: =O25 -> 0 | T25: =H25*L25 -> 0 | W25: =IFERROR(VLOOKUP(A25,거래처!B:Z,21,0),"") -> （주）디투어패럴
A26: 리마인드 | B26: 경기도 고양시 일산동구 지영로 59-2 D동 | C26: 010-3918-2418 | D26: 010-9208-6514 | E26: S22131 | F26: 4503 [반바지] | G26: 아이보리/M | H26: 10000 | K26: 1 | R26: 8/18 더안불량(오염) | S26: =O26 -> 0 | T26: =H26*L26 -> 0 | W26: =IFERROR(VLOOKUP(A26,거래처!B:Z,21,0),"") -> （주）디투어패럴
A27: 리마인드 | B27: 경기도 고양시 일산동구 지영로 59-2 D동 | C27: 010-3918-2418 | D27: 010-9208-6514 | E27: S19666 | F27: 5100-3pt [부츠컷] | G27: 연청/M | H27: 14000 | K27: 1 | R27: 8/6 더안불량(오입고) | S27: =O27 -> 0 | T27: =H27*L27 -> 0 | W27: =IFERROR(VLOOKUP(A27,거래처!B:Z,21,0),"") -> （주）디투어패럴
A28: 리마인드 | B28: 경기도 고양시 일산동구 지영로 59-2 D동 | C28: 010-3918-2418 | D28: 010-9208-6514 | E28: S19665 | F28: 5100-3pt [부츠컷] | G28: 연청/S | H28: 14000 | K28: 1 | R28: 8/27 더안불량(허리부분오염) | S28: =O28 -> 0 | T28: =H28*L28 -> 0 | W28: =IFERROR(VLOOKUP(A28,거래처!B:Z,21,0),"") -> （주）디투어패럴
A29: 리마인드 | B29: 경기도 고양시 일산동구 지영로 59-2 D동 | C29: 010-3918-2418 | D29: 010-9208-6514 | E29: S19243 | F29: 5106-5pt [와이드] | G29: 화이트(M,롱) | H29: 13000 | K29: 3 | R29: 8/27 더안불량(오염) | S29: =O29 -> 0 | T29: =H29*L29 -> 0 | W29: =IFERROR(VLOOKUP(A29,거래처!B:Z,21,0),"") -> （주）디투어패럴
A30: 리마인드 | B30: 경기도 고양시 일산동구 지영로 59-2 D동 | C30: 010-3918-2418 | D30: 010-9208-6514 | E30: S19241 | F30: 5106-5pt [와이드] | G30: 화이트(S,롱) | H30: 13000 | K30: 1 | R30: 8/18 더안불량(오염) | S30: =O30 -> 0 | T30: =H30*L30 -> 0 | W30: =IFERROR(VLOOKUP(A30,거래처!B:Z,21,0),"") -> （주）디투어패럴
A31: 리마인드 | B31: 경기도 고양시 일산동구 지영로 59-2 D동 | C31: 010-3918-2418 | D31: 010-9208-6514 | E31: S19240 | F31: 5106-5pt [와이드] | G31: 화이트(S,숏) | H31: 13000 | K31: 1 | R31: 8/18 더안불량(오염) | S31: =O31 -> 0 | T31: =H31*L31 -> 0 | W31: =IFERROR(VLOOKUP(A31,거래처!B:Z,21,0),"") -> （주）디투어패럴
A32: 리마인드 | B32: 경기도 고양시 일산동구 지영로 59-2 D동 | C32: 010-3918-2418 | D32: 010-9208-6514 | E32: S22018 | F32: 5412nt [반팔] | G32: 베이지 | H32: 11000 | K32: 1 | R32: 8/14 더안불량(앞면 오염) | S32: =O32 -> 0 | T32: =H32*L32 -> 0 | W32: =IFERROR(VLOOKUP(A32,거래처!B:Z,21,0),"") -> （주）디투어패럴
A33: 리마인드 | B33: 경기도 고양시 일산동구 지영로 59-2 D동 | C33: 010-3918-2418 | D33: 010-9208-6514 | E33: S19243 | F33: 5106-5pt [와이드] | G33: 화이트(M,롱) | H33: 13000 | R33: 8/28 더안불량(오염,잡사) | S33: =O33 -> 0 | T33: =H33*L33 -> 0 | W33: =IFERROR(VLOOKUP(A33,거래처!B:Z,21,0),"") -> （주）디투어패럴
A34: 리마인드 | B34: 경기도 고양시 일산동구 지영로 59-2 D동 | C34: 010-3918-2418 | D34: 010-9208-6514 | E34: S23477 | F34: 5409nt [반팔] | G34: 화이트 | H34: 9000 | R34: 8/28 더안불량(오염,봉제불량) | S34: =O34 -> 0 | T34: =H34*L34 -> 0 | W34: =IFERROR(VLOOKUP(A34,거래처!B:Z,21,0),"") -> （주）디투어패럴
S35: =O35 -> 0 | T35: =H35*L35 -> 0 | W35: =IFERROR(VLOOKUP(A35,거래처!B:Z,21,0),"")
A36: KDG(부가세) | B36: 경기도 용인시 처인구 포곡읍 둔전로 49 | C36: 010-5818-0264 | D36: 010-5818-0264 | E36: S22537 | F36: 4081-1pt [부츠컷] | G36: 흑청/L/기본 | H36: 12500 | I36: 1 | L36: 1 | S36: =O36 -> 0 | T36: =H36*L36 -> 12500 | W36: =IFERROR(VLOOKUP(A36,거래처!B:Z,21,0),"") -> 케이디지
S37: =O37 -> 0 | T37: =H37*L37 -> 0 | W37: =IFERROR(VLOOKUP(A37,거래처!B:Z,21,0),"")
A38: 슬로그(누죤) | B38: 누죤 3층 429 | C38: 010-8780-0823 | D38: 010-8780-0823 | E38: S20982 | F38: 네스v넥 [반팔] | G38: 네이비 | H38: 14000 | I38: 1 | L38: 1 | S38: =O38 -> 0 | T38: =H38*L38 -> 14000 | W38: =IFERROR(VLOOKUP(A38,거래처!B:Z,21,0),"") -> 윤상원
A39: 슬로그(누죤) | B39: 누죤 3층 429 | C39: 010-8780-0823 | D39: 010-8780-0823 | E39: S20983 | F39: 네스v넥 [반팔] | G39: 멜란지 | H39: 14000 | I39: 1 | L39: 1 | S39: =O39 -> 0 | T39: =H39*L39 -> 14000 | W39: =IFERROR(VLOOKUP(A39,거래처!B:Z,21,0),"") -> 윤상원
A40: 슬로그(누죤) | B40: 누죤 3층 429 | C40: 010-8780-0823 | D40: 010-8780-0823 | E40: S21032 | F40: 카라배색빌리프 [반팔] | G40: 네이비 | H40: 15000 | I40: 1 | L40: 1 | S40: =O40 -> 0 | T40: =H40*L40 -> 15000 | W40: =IFERROR(VLOOKUP(A40,거래처!B:Z,21,0),"") -> 윤상원
S41: =O41 -> 0 | T41: =H41*L41 -> 0 | W41: =IFERROR(VLOOKUP(A41,거래처!B:Z,21,0),"")
A42: 페이브 | B42: 누죤 4층 605 | C42: 010-3917-9639 | D42: 010-3917-9639 | E42: S18729 | F42: 투미목걸이 | G42: 실버 | H42: 4000 | I42: 20 | L42: 20 | S42: =O42 -> 0 | T42: =H42*L42 -> 80000 | W42: =IFERROR(VLOOKUP(A42,거래처!B:Z,21,0),"") -> 이나은(페이브)
...

Sheet 0827
A1: 가나다란 08/27(수밤) 주문서 | I1: 발주 | L1: 장끼 | O1: 입고 | P1: 차이
A2: 거래처명 | B2: 공급처주소 | C2: 공급처연락처 | D2: 공급처휴대전화 | E2: 상품코드 | F2: 공급처상품명 | G2: 공급처옵션 | H2: 원가 | I2: 신규주문 | J2: 미송 | K2: 교환 | L2: 장끼 | M2: 미송 | N2: 교환 | O2: 주문 | P2: 주문 | Q2: 삼촌 코멘트 | R2: 가나다란 코멘트 | S2: 실입고수 | T2: 오늘입금할금액 | U2: 미송/매입금액 | V2: 입금일 | W2: 공급처예금주
I3: 1886 | J3: 1111 | K3: 93 | L3: 837 | M3: 106 | N3: 7 | O3: 950 | P3: 0 | Q3: 0 | R3: 0 | S3: 950 | T3: 13811650 | U3: 16160500
Q4: ※ 주문서 작성시 KDG, 제이와이엠, 디피프로젝트 카톡 채널 공유 필수 | S4: 0 | T4: 0
A5: 썸 | B5: 본사반출 | F5: 시스루BL | G5: 검정 | R5: 08/26 본사반출 | S5: 0 | T5: 0 | W5: 홍성복
S6: 0 | T6: 0
A7: 리마인드 | B7: 경기도 고양시 일산동구 지영로 59-2 D동 | C7: 010-3918-2418 | D7: 010-9208-6514 | E7: S16834 | F7: 2420(부츠)sl (C) | G7: 블랙(숏L) | H7: 12000 | I7: 1 | L7: 1 | O7: 1 | S7: 1 | T7: 12000 | W7: （주）디투어패럴
A8: 리마인드 | B8: 경기도 고양시 일산동구 지영로 59-2 D동 | C8: 010-3918-2418 | D8: 010-9208-6514 | E8: S16796 | F8: 2420(부츠)sl (C) | G8: 아이보리(숏S) | H8: 12000 | I8: 1 | L8: 1 | O8: 1 | S8: 1 | T8: 12000 | W8: （주）디투어패럴
A9: 리마인드 | B9: 경기도 고양시 일산동구 지영로 59-2 D동 | C9: 010-3918-2418 | D9: 010-9208-6514 | E9: S16828 | F9: 2420(부츠)sl (C) | G9: 회색(기본L) | H9: 12000 | I9: 1 | L9: 1 | O9: 1 | S9: 1 | T9: 12000 | W9: （주）디투어패럴
A10: 리마인드 | B10: 경기도 고양시 일산동구 지영로 59-2 D동 | C10: 010-3918-2418 | D10: 010-9208-6514 | E10: S16823 | F10: 2420(부츠)sl (C) | G10: 회색(숏S) | H10: 12000 | I10: 1 | L10: 1 | O10: 1 | S10: 1 | T10: 12000 | W10: （주）디투어패럴
A11: 리마인드 | B11: 경기도 고양시 일산동구 지영로 59-2 D동 | C11: 010-3918-2418 | D11: 010-9208-6514 | E11: S22136 | F11: 4503 [반바지] | G11: 블랙/S | H11: 10000 | I11: 1 | L11: 1 | O11: 1 | S11: 1 | T11: 10000 | W11: （주）디투어패럴
A12: 리마인드 | B12: 경기도 고양시 일산동구 지영로 59-2 D동 | C12: 010-3918-2418 | D12: 010-9208-6514 | E12: S22130 | F12: 4503 [반바지] | G12: 아이보리/S | H12: 10000 | I12: 5 | L12: 5 | O12: 5 | S12: 5 | T12: 50000 | W12: （주）디투어패럴
A13: 리마인드 | B13: 경기도 고양시 일산동구 지영로 59-2 D동 | C13: 010-3918-2418 | D13: 010-9208-6514 | E13: S18813 | F13: 5007pt [부츠컷] | G13: 중청(M) | H13: 15000 | I13: 1 | L13: 1 | O13: 1 | S13: 1 | T13: 15000 | W13: （주）디투어패럴
A14: 리마인드 | B14: 경기도 고양시 일산동구 지영로 59-2 D동 | C14: 010-3918-2418 | D14: 010-9208-6514 | E14: S19666 | F14: 5100-3pt [부츠컷] | G14: 연청/M | H14: 14000 | I14: 1 | L14: 1 | O14: 1 | S14: 1 | T14: 14000 | W14: （주）디투어패럴
A15: 리마인드 | B15: 경기도 고양시 일산동구 지영로 59-2 D동 | C15: 010-3918-2418 | D15: 010-9208-6514 | E15: S19665 | F15: 5100-3pt [부츠컷] | G15: 연청/S | H15: 14000 | I15: 1 | L15: 1 | O15: 1 | S15: 1 | T15: 14000 | W15: （주）디투어패럴
A16: 리마인드 | B16: 경기도 고양시 일산동구 지영로 59-2 D동 | C16: 010-3918-2418 | D16: 010-9208-6514 | E16: S19244 | F16: 5106-5pt [와이드] | G16: 화이트(L,숏) | H16: 13000 | I16: 1 | L16: 1 | O16: 1 | S16: 1 | T16: 13000 | W16: （주）디투어패럴
A17: 리마인드 | B17: 경기도 고양시 일산동구 지영로 59-2 D동 | C17: 010-3918-2418 | D17: 010-9208-6514 | E17: S19243 | F17: 5106-5pt [와이드] | G17: 화이트(M,롱) | H17: 13000 | I17: 5 | L17: 5 | O17: 5 | S17: 5 | T17: 65000 | W17: （주）디투어패럴
A18: 리마인드 | B18: 경기도 고양시 일산동구 지영로 59-2 D동 | C18: 010-3918-2418 | D18: 010-9208-6514 | E18: S23476 | F18: 5409nt [반팔] | G18: 핑크 | H18: 9000 | I18: 2 | L18: 2 | O18: 2 | S18: 2 | T18: 18000 | W18: （주）디투어패럴
A19: 리마인드 | B19: 경기도 고양시 일산동구 지영로 59-2 D동 | C19: 010-3918-2418 | D19: 010-9208-6514 | E19: S23477 | F19: 5409nt [반팔] | G19: 화이트 | H19: 9000 | I19: 3 | L19: 3 | O19: 3 | S19: 3 | T19: 27000 | W19: （주）디투어패럴
A20: 리마인드 | B20: 경기도 고양시 일산동구 지영로 59-2 D동 | C20: 010-3918-2418 | D20: 010-9208-6514 | E20: S16811 | F20: 2420(부츠)sl (C) | G20: 베이지(롱S) | H20: 12000 | K20: 1 | O20: 0 | R20: 8/21 더안불량(오염) | S20: 0 | T20: 0 | W20: （주）디투어패럴
A21: 리마인드 | B21: 경기도 고양시 일산동구 지영로 59-2 D동 | C21: 010-3918-2418 | D21: 010-9208-6514 | E21: S16800 | F21: 2420(부츠)sl (C) | G21: 아이보리(기본M) | H21: 12000 | K21: 1 | O21: 0 | R21: 8/13 더안불량(오염) | S21: 0 | T21: 0 | W21: （주）디투어패럴
A22: 리마인드 | B22: 경기도 고양시 일산동구 지영로 59-2 D동 | C22: 010-3918-2418 | D22: 010-9208-6514 | E22: S16796 | F22: 2420(부츠)sl (C) | G22: 아이보리(숏S) | H22: 12000 | K22: 1 | O22: 0 | R22: 8/21 더안불량(오염) | S22: 0 | T22: 0 | W22: （주）디투어패럴
A23: 리마인드 | B23: 경기도 고양시 일산동구 지영로 59-2 D동 | C23: 010-3918-2418 | D23: 010-9208-6514 | E23: S22136 | F23: 4503 [반바지] | G23: 블랙/S | H23: 10000 | K23: 1 | O23: 0 | R23: 8/18 더안불량(양쪽길이 다름) | S23: 0 | T23: 0 | W23: （주）디투어패럴
A24: 리마인드 | B24: 경기도 고양시 일산동구 지영로 59-2 D동 | C24: 010-3918-2418 | D24: 010-9208-6514 | E24: S22131 | F24: 4503 [반바지] | G24: 아이보리/M | H24: 10000 | K24: 1 | O24: 0 | R24: 8/18 더안불량(오염) | S24: 0 | T24: 0 | W24: （주）디투어패럴
A25: 리마인드 | B25: 경기도 고양시 일산동구 지영로 59-2 D동 | C25: 010-3918-2418 | D25: 010-9208-6514 | E25: S19666 | F25: 5100-3pt [부츠컷] | G25: 연청/M | H25: 14000 | K25: 1 | O25: 0 | R25: 8/6 더안불량(오입고) | S25: 0 | T25: 0 | W25: （주）디투어패럴
A26: 리마인드 | B26: 경기도 고양시 일산동구 지영로 59-2 D동 | C26: 010-3918-2418 | D26: 010-9208-6514 | E26: S19241 | F26: 5106-5pt [와이드] | G26: 화이트(S,롱) | H26: 13000 | K26: 1 | O26: 0 | R26: 8/18 더안불량(오염) | S26: 0 | T26: 0 | W26: （주）디투어패럴
A27: 리마인드 | B27: 경기도 고양시 일산동구 지영로 59-2 D동 | C27: 010-3918-2418 | D27: 010-9208-6514 | E27: S19240 | F27: 5106-5pt [와이드] | G27: 화이트(S,숏) | H27: 13000 | K27: 1 | O27: 0 | R27: 8/18 더안불량(오염) | S27: 0 | T27: 0 | W27: （주）디투어패럴
A28: 리마인드 | B28: 경기도 고양시 일산동구 지영로 59-2 D동 | C28: 010-3918-2418 | D28: 010-9208-6514 | E28: S22018 | F28: 5412nt [반팔] | G28: 베이지 | H28: 11000 | K28: 1 | O28: 0 | R28: 8/14 더안불량(앞면 오염) | S28: 0 | T28: 0 | W28: （주）디투어패럴
A29: 리마인드 | B29: 경기도 고양시 일산동구 지영로 59-2 D동 | C29: 010-3918-2418 | D29: 010-9208-6514 | E29: S19665 | F29: 5100-3pt [부츠컷] | G29: 연청/S | H29: 14000 | K29: 1 | O29: 0 | R29: 8/27 더안불량(허리부분오염) | S29: 0 | T29: 0 | W29: （주）디투어패럴
A30: 리마인드 | B30: 경기도 고양시 일산동구 지영로 59-2 D동 | C30: 010-3918-2418 | D30: 010-9208-6514 | E30: S19243 | F30: 5106-5pt [와이드] | G30: 화이트(M,롱) | H30: 13000 | K30: 3 | O30: 0 | R30: 8/27 더안불량(오염) | S30: 0 | T30: 0 | W30: （주）디투어패럴
A31: 리마인드 | B31: 경기도 고양시 일산동구 지영로 59-2 D동 | C31: 010-3918-2418 | D31: 010-9208-6514 | E31: S19243 | F31: 5106-5pt [와이드] | G31: 화이트(M,롱) | H31: 13000 | O31: 0 | R31: 8/28 더안불량(오염,잡사) | S31: 0 | T31: 0 | W31: （주）디투어패럴
A32: 리마인드 | B32: 경기도 고양시 일산동구 지영로 59-2 D동 | C32: 010-3918-2418 | D32: 010-9208-6514 | E32: S23477 | F32: 5409nt [반팔] | G32: 화이트 | H32: 9000 | O32: 0 | R32: 8/28 더안불량(오염,봉제불량) | S32: 0 | T32: 0 | W32: （주）디투어패럴
O33: 0 | S33: 0 | T33: 0
A34: KDG(부가세) | B34: 경기도 용인시 처인구 포곡읍 둔전로 49 | C34: 010-5818-0264 | D34: 010-5818-0264 | E34: S22531 | F34: 4081-1pt [부츠컷] | G34: 흑청/S/기본 | H34: 12500 | I34: 1 | L34: 1 | O34: 1 | S34: 1 | T34: 12500 | W34: 케이디지
A35: KDG(부가세) | B35: 경기도 용인시 처인구 포곡읍 둔전로 49 | C35: 010-5818-0264 | D35: 010-5818-0264 | R35: 08/28 부가세 | S35: 0 | T35: 1250 | W35: 케이디지
O36: 0 | S36: 0 | T36: 0
A37: 슬로그(누죤) | B37: 누죤 3층 429 | C37: 010-8780-0823 | D37: 010-8780-0823 | E37: S20981 | F37: 네스v넥 [반팔] | G37: 검정 | H37: 14000 | I37: 1 | L37: 1 | O37: 1 | S37: 1 | T37: 14000 | W37: 윤상원
A38: 슬로그(누죤) | B38: 누죤 3층 429 | C38: 010-8780-0823 | D38: 010-8780-0823 | E38: S20985 | F38: 네스v넥 [반팔] | G38: 크림 | H38: 14000 | I38: 2 | L38: 2 | O38: 2 | S38: 2 | T38: 28000 | W38: 윤상원
A39: 슬로그(누죤) | B39: 누죤 3층 429 | C39: 010-8780-0823 | D39: 010-8780-0823 | E39: S20770 | F39: 빌리프골지카라니트 [반팔] | G39: 검정 | H39: 15000 | I39: 3 | L39: 3 | O39: 3 | S39: 3 | T39: 45000 | W39: 윤상원
A40: 슬로그(누죤) | B40: 누죤 3층 429 | C40: 010-8780-0823 | D40: 010-8780-0823 | E40: S20771 | F40: 빌리프골지카라니트 [반팔] | G40: 멜란지 | H40: 15000 | I40: 2 | L40: 1 | O40: 1 | Q40: 나머지 목밤 | S40: 1 | T40: 15000 | W40: 윤상원
...

Sheet 0826
A1: 가나다란 08/26(화밤) 주문서 | I1: 발주 | L1: 장끼 | O1: 입고 | P1: 차이
A2: 거래처명 | B2: 공급처주소 | C2: 공급처연락처 | D2: 공급처휴대전화 | E2: 상품코드 | F2: 공급처상품명 | G2: 공급처옵션 | H2: 원가 | I2: 신규주문 | J2: 미송 | K2: 교환 | L2: 장끼 | M2: 미송 | N2: 교환 | O2: 주문 | P2: 주문 | Q2: 삼촌 코멘트 | R2: 가나다란 코멘트 | S2: 실입고수 | T2: 오늘입금할금액 | U2: 미송/매입금액 | V2: 입금일 | W2: 공급처예금주
I3: 1477 | J3: 1641 | K3: 112 | L3: 783 | M3: 626 | N3: 8 | O3: 1439 | P3: 0 | Q3: 0 | R3: 0 | S3: 585 | T3: 10614150 | U3: 22640400 | V3: 4589229
Q4: ※ 주문서 작성시 KDG, 제이와이엠, 디피프로젝트 카톡 채널 공유 필수 | S4: 0 | T4: 0
A5: 썸 | B5: 본사반출 | F5: 시스루BL | G5: 검정 | R5: 08/26 본사반출 | S5: 0 | T5: 0 | W5: 홍성복
S6: 0 | T6: 0
A7: 리마인드 | B7: 경기도 고양시 일산동구 지영로 59-2 D동 | C7: 010-3918-2418 | D7: 010-9208-6514 | E7: S16836 | F7: 2420(부츠)sl (C) | G7: 블랙(기본M) | H7: 12000 | I7: 10 | L7: 10 | O7: 10 | S7: 10 | T7: 120000 | W7: （주）디투어패럴
A8: 리마인드 | B8: 경기도 고양시 일산동구 지영로 59-2 D동 | C8: 010-3918-2418 | D8: 010-9208-6514 | E8: S16839 | F8: 2420(부츠)sl (C) | G8: 블랙(롱M) | H8: 12000 | I8: 5 | L8: 5 | O8: 5 | S8: 5 | T8: 60000 | W8: （주）디투어패럴
A9: 리마인드 | B9: 경기도 고양시 일산동구 지영로 59-2 D동 | C9: 010-3918-2418 | D9: 010-9208-6514 | E9: S22136 | F9: 4503 [반바지] | G9: 블랙/S | H9: 10000 | I9: 1 | L9: 1 | O9: 1 | S9: 1 | T9: 10000 | W9: （주）디투어패럴
A10: 리마인드 | B10: 경기도 고양시 일산동구 지영로 59-2 D동 | C10: 010-3918-2418 | D10: 010-9208-6514 | E10: S22130 | F10: 4503 [반바지] | G10: 아이보리/S | H10: 10000 | I10: 5 | L10: 5 | O10: 5 | S10: 5 | T10: 50000 | W10: （주）디투어패럴
A11: 리마인드 | B11: 경기도 고양시 일산동구 지영로 59-2 D동 | C11: 010-3918-2418 | D11: 010-9208-6514 | E11: S19243 | F11: 5106-5pt [와이드] | G11: 화이트(M,롱) | H11: 13000 | I11: 7 | L11: 7 | O11: 7 | S11: 7 | T11: 91000 | W11: （주）디투어패럴
A12: 리마인드 | B12: 경기도 고양시 일산동구 지영로 59-2 D동 | C12: 010-3918-2418 | D12: 010-9208-6514 | E12: S22018 | F12: 5412nt [반팔] | G12: 베이지 | H12: 9000 | I12: 3 | L12: 3 | O12: 3 | S12: 3 | T12: 27000 | W12: （주）디투어패럴
A13: 리마인드 | B13: 경기도 고양시 일산동구 지영로 59-2 D동 | C13: 010-3918-2418 | D13: 010-9208-6514 | E13: S22019 | F13: 5412nt [반팔] | G13: 블랙 | H13: 9000 | I13: 2 | L13: 2 | O13: 2 | S13: 2 | T13: 18000 | W13: （주）디투어패럴
A14: 리마인드 | B14: 경기도 고양시 일산동구 지영로 59-2 D동 | C14: 010-3918-2418 | D14: 010-9208-6514 | E14: S21624 | F14: 5507pt [와이드] | G14: 진청(5507-1)/L | H14: 16000 | I14: 1 | L14: 1 | O14: 1 | S14: 1 | T14: 16000 | W14: （주）디투어패럴
A15: 리마인드 | B15: 경기도 고양시 일산동구 지영로 59-2 D동 | C15: 010-3918-2418 | D15: 010-9208-6514 | E15: S16811 | F15: 2420(부츠)sl (C) | G15: 베이지(롱S) | H15: 12000 | K15: 1 | O15: 0 | R15: 8/21 더안불량(오염) | S15: 0 | T15: 0 | W15: （주）디투어패럴
A16: 리마인드 | B16: 경기도 고양시 일산동구 지영로 59-2 D동 | C16: 010-3918-2418 | D16: 010-9208-6514 | E16: S16800 | F16: 2420(부츠)sl (C) | G16: 아이보리(기본M) | H16: 12000 | K16: 1 | O16: 0 | R16: 8/13 더안불량(오염) | S16: 0 | T16: 0 | W16: （주）디투어패럴
A17: 리마인드 | B17: 경기도 고양시 일산동구 지영로 59-2 D동 | C17: 010-3918-2418 | D17: 010-9208-6514 | E17: S16796 | F17: 2420(부츠)sl (C) | G17: 아이보리(숏S) | H17: 12000 | K17: 1 | O17: 0 | R17: 8/21 더안불량(오염) | S17: 0 | T17: 0 | W17: （주）디투어패럴
A18: 리마인드 | B18: 경기도 고양시 일산동구 지영로 59-2 D동 | C18: 010-3918-2418 | D18: 010-9208-6514 | E18: S22136 | F18: 4503 [반바지] | G18: 블랙/S | H18: 10000 | K18: 1 | O18: 0 | R18: 8/18 더안불량(양쪽길이 다름) | S18: 0 | T18: 0 | W18: （주）디투어패럴
A19: 리마인드 | B19: 경기도 고양시 일산동구 지영로 59-2 D동 | C19: 010-3918-2418 | D19: 010-9208-6514 | E19: S22131 | F19: 4503 [반바지] | G19: 아이보리/M | H19: 10000 | K19: 1 | O19: 0 | R19: 8/18 더안불량(오염) | S19: 0 | T19: 0 | W19: （주）디투어패럴
A20: 리마인드 | B20: 경기도 고양시 일산동구 지영로 59-2 D동 | C20: 010-3918-2418 | D20: 010-9208-6514 | E20: S19666 | F20: 5100-3pt [부츠컷] | G20: 연청/M | H20: 14000 | K20: 1 | O20: 0 | R20: 8/6 더안불량(오입고) | S20: 0 | T20: 0 | W20: （주）디투어패럴
A21: 리마인드 | B21: 경기도 고양시 일산동구 지영로 59-2 D동 | C21: 010-3918-2418 | D21: 010-9208-6514 | E21: S19241 | F21: 5106-5pt [와이드] | G21: 화이트(S,롱) | H21: 13000 | K21: 1 | O21: 0 | R21: 8/18 더안불량(오염) | S21: 0 | T21: 0 | W21: （주）디투어패럴
A22: 리마인드 | B22: 경기도 고양시 일산동구 지영로 59-2 D동 | C22: 010-3918-2418 | D22: 010-9208-6514 | E22: S19240 | F22: 5106-5pt [와이드] | G22: 화이트(S,숏) | H22: 13000 | K22: 1 | O22: 0 | R22: 8/18 더안불량(오염) | S22: 0 | T22: 0 | W22: （주）디투어패럴
A23: 리마인드 | B23: 경기도 고양시 일산동구 지영로 59-2 D동 | C23: 010-3918-2418 | D23: 010-9208-6514 | E23: S22018 | F23: 5412nt [반팔] | G23: 베이지 | H23: 11000 | K23: 1 | O23: 0 | R23: 8/14 더안불량(앞면 오염) | S23: 0 | T23: 0 | W23: （주）디투어패럴
A24: 리마인드 | B24: 경기도 고양시 일산동구 지영로 59-2 D동 | C24: 010-3918-2418 | D24: 010-9208-6514 | E24: S19665 | F24: 5100-3pt [부츠컷] | G24: 연청/S | H24: 14000 | K24: 1 | O24: 0 | R24: 8/27 더안불량(허리부분오염) | S24: 0 | T24: 0 | W24: （주）디투어패럴
A25: 리마인드 | B25: 경기도 고양시 일산동구 지영로 59-2 D동 | C25: 010-3918-2418 | D25: 010-9208-6514 | E25: S19243 | F25: 5106-5pt [와이드] | G25: 화이트(M,롱) | H25: 13000 | K25: 3 | O25: 0 | R25: 8/27 더안불량(오염) | S25: 0 | T25: 0 | W25: （주）디투어패럴
O26: 0 | S26: 0 | T26: 0
A27: KDG(부가세) | B27: 경기도 용인시 처인구 포곡읍 둔전로 49 | C27: 010-5818-0264 | D27: 010-5818-0264 | E27: S22535 | F27: 4081-1pt [부츠컷] | G27: 흑청/M/롱 | H27: 12500 | I27: 2 | L27: 2 | O27: 2 | S27: 2 | T27: 25000 | W27: 케이디지
A28: KDG(부가세) | B28: 경기도 용인시 처인구 포곡읍 둔전로 49 | C28: 010-5818-0264 | D28: 010-5818-0264 | E28: S22533 | F28: 4081-1pt [부츠컷] | G28: 흑청/M/숏 | H28: 12500 | I28: 1 | L28: 1 | O28: 1 | S28: 1 | T28: 12500 | W28: 케이디지
A29: KDG(부가세) | B29: 경기도 용인시 처인구 포곡읍 둔전로 49 | C29: 010-5818-0264 | D29: 010-5818-0264 | F29: 샘플픽업 | O29: 0 | Q29: OK | S29: 0 | T29: 0 | W29: 케이디지
A30: KDG(부가세) | B30: 경기도 용인시 처인구 포곡읍 둔전로 49 | C30: 010-5818-0264 | D30: 010-5818-0264 | O30: 0 | R30: 08/27 부가세 | S30: 0 | T30: 3750 | W30: 케이디지
O31: 0 | S31: 0 | T31: 0
A32: 마젠타 | B32: 남평화 3층 가-15,16 | C32: 010-3801-1516 | D32: 010-3801-1516 | E32: S16411 | F32: 부드러운반목니트반팔 [5부] | G32: 회색 | H32: 6000 | I32: 1 | L32: 1 | O32: 1 | S32: 1 | T32: 6000 | W32: (주)마젠타어패럴그
O33: 0 | S33: 0 | T33: 0
A34: 리머블 | B34: 남평화 지하 1층 B-14 | C34: 010-7761-8021 | D34: 010-7761-8021 | E34: S22866 | F34: 8900 [가방] | G34: 블랙 | H34: 13000 | I34: 1 | O34: 0 | Q34: 칼라품절 | S34: 0 | T34: 0 | W34: 정자영(리머블)
O35: 0 | S35: 0 | T35: 0
A36: 메바 | B36: 남평화 지하 1층 신관 20,21 | C36: 02-2235-0231 | D36: 010-9988-0231 | F36: 샘플픽업 | O36: 0 | Q36: OK | S36: 0 | T36: 0 | W36: 한관수
O37: 0 | S37: 0 | T37: 0
A38: 슬로그(누죤) | B38: 누죤 3층 429 | C38: 010-8780-0823 | D38: 010-8780-0823 | E38: S20771 | F38: 빌리프골지카라니트 [반팔] | G38: 멜란지 | H38: 15000 | I38: 1 | L38: 1 | O38: 1 | S38: 1 | T38: 15000 | W38: 윤상원
O39: 0 | S39: 0 | T39: 0
A40: 페이브 | B40: 누죤 4층 605 | C40: 010-3917-9639 | D40: 010-3917-9639 | E40: S18729 | F40: 투미목걸이 | G40: 실버 | H40: 4000 | I40: 30 | L40: 30 | O40: 30 | S40: 30 | T40: 120000 | W40: 이나은(페이브)
...

Sheet 0825
A1: 가나다란 08/25(월밤) 주문서 | I1: 발주 | L1: 장끼 | O1: 입고 | P1: 차이
A2: 거래처명 | B2: 공급처주소 | C2: 공급처연락처 | D2: 공급처휴대전화 | E2: 상품코드 | F2: 공급처상품명 | G2: 공급처옵션 | H2: 원가 | I2: 신규주문 | J2: 미송 | K2: 교환 | L2: 장끼 | M2: 미송 | N2: 교환 | O2: 주문 | P2: 주문 | Q2: 삼촌 코멘트 | R2: 가나다란 코멘트 | S2: 실입고수 | T2: 오늘입금할금액 | U2: 미송/매입금액 | V2: 입금일 | W2: 공급처예금주
I3: 1865 | J3: 1859 | K3: 109 | L3: 1118 | M3: 368 | N3: 5 | O3: 1491 | P3: 0 | Q3: 0 | R3: 0 | S3: 1491 | T3: 15126600 | U3: 26049900 | V3: 5277501
Q4: ※ 주문서 작성시 KDG, 제이와이엠, 디피프로젝트 카톡 채널 공유 필수 | S4: 0 | T4: 0
A5: 래래 | B5: 본사반출 | E5: S23304 | F5: 벨트sl | G5: 진베이지/s/롱 | K5: 1 | R5: 08/19 본사반출(코디, 촬영용 - 결제 완료) | S5: 0 | T5: 0 | W5: 김래영（래래（ＲＡＥ
A6: 래래 | B6: 본사반출 | E6: S23312 | F6: 벨트sl | G6: 블랙/s/롱 | K6: 1 | R6: 08/19 본사반출(코디, 촬영용 - 결제 완료) | S6: 0 | T6: 0 | W6: 김래영（래래（ＲＡＥ
A7: 래래 | B7: 본사반출 | E7: S23300 | F7: 벨트sl | G7: 아이/s/롱 | K7: 1 | R7: 08/19 본사반출(코디, 촬영용 - 결제 완료) | S7: 0 | T7: 0 | W7: 김래영（래래（ＲＡＥ
A8: 래래 | B8: 본사반출 | E8: S23308 | F8: 벨트sl | G8: 진그레이/s/롱 | K8: 1 | R8: 08/19 본사반출(코디, 촬영용 - 결제 완료) | S8: 0 | T8: 0 | W8: 김래영（래래（ＲＡＥ
A9: 래래 | B9: 본사반출 | E9: S23316 | F9: 벨트sl | G9: 브라운/s/롱 | K9: 1 | R9: 08/19 본사반출(코디, 촬영용 - 결제 완료) | S9: 0 | T9: 0 | W9: 김래영（래래（ＲＡＥ
S10: 0 | T10: 0
A11: 리마인드 | B11: 경기도 고양시 일산동구 지영로 59-2 D동 | C11: 010-3918-2418 | D11: 010-9208-6514 | E11: S16840 | F11: 2420(부츠)sl (C) | G11: 블랙(롱L) | H11: 12000 | I11: 1 | L11: 1 | O11: 1 | S11: 1 | T11: 12000 | W11: （주）디투어패럴
A12: 리마인드 | B12: 경기도 고양시 일산동구 지영로 59-2 D동 | C12: 010-3918-2418 | D12: 010-9208-6514 | E12: S16832 | F12: 2420(부츠)sl (C) | G12: 블랙(숏S) | H12: 12000 | I12: 1 | L12: 1 | O12: 1 | S12: 1 | T12: 12000 | W12: （주）디투어패럴
A13: 리마인드 | B13: 경기도 고양시 일산동구 지영로 59-2 D동 | C13: 010-3918-2418 | D13: 010-9208-6514 | E13: S22132 | F13: 4503 [반바지] | G13: 아이보리/L | H13: 10000 | I13: 1 | L13: 1 | O13: 1 | S13: 1 | T13: 10000 | W13: （주）디투어패럴
A14: 리마인드 | B14: 경기도 고양시 일산동구 지영로 59-2 D동 | C14: 010-3918-2418 | D14: 010-9208-6514 | E14: S18813 | F14: 5007pt [부츠컷] | G14: 중청(M) | H14: 15000 | I14: 1 | L14: 1 | O14: 1 | S14: 1 | T14: 15000 | W14: （주）디투어패럴
A15: 리마인드 | B15: 경기도 고양시 일산동구 지영로 59-2 D동 | C15: 010-3918-2418 | D15: 010-9208-6514 | E15: S19243 | F15: 5106-5pt [와이드] | G15: 화이트(M,롱) | H15: 13000 | I15: 1 | L15: 1 | O15: 1 | S15: 1 | T15: 13000 | W15: （주）디투어패럴
A16: 리마인드 | B16: 경기도 고양시 일산동구 지영로 59-2 D동 | C16: 010-3918-2418 | D16: 010-9208-6514 | E16: S21623 | F16: 5507pt [와이드] | G16: 진청(5507-1)/M | H16: 16000 | I16: 2 | L16: 2 | O16: 2 | S16: 2 | T16: 32000 | W16: （주）디투어패럴
A17: 리마인드 | B17: 경기도 고양시 일산동구 지영로 59-2 D동 | C17: 010-3918-2418 | D17: 010-9208-6514 | E17: S21622 | F17: 5507pt [와이드] | G17: 진청(5507-1)/S | H17: 16000 | I17: 1 | L17: 1 | O17: 1 | S17: 1 | T17: 16000 | W17: （주）디투어패럴
A18: 리마인드 | B18: 경기도 고양시 일산동구 지영로 59-2 D동 | C18: 010-3918-2418 | D18: 010-9208-6514 | E18: S16811 | F18: 2420(부츠)sl (C) | G18: 베이지(롱S) | H18: 12000 | K18: 1 | O18: 0 | R18: 8/21 더안불량(오염) | S18: 0 | T18: 0 | W18: （주）디투어패럴
A19: 리마인드 | B19: 경기도 고양시 일산동구 지영로 59-2 D동 | C19: 010-3918-2418 | D19: 010-9208-6514 | E19: S16800 | F19: 2420(부츠)sl (C) | G19: 아이보리(기본M) | H19: 12000 | K19: 1 | O19: 0 | R19: 8/13 더안불량(오염) | S19: 0 | T19: 0 | W19: （주）디투어패럴
A20: 리마인드 | B20: 경기도 고양시 일산동구 지영로 59-2 D동 | C20: 010-3918-2418 | D20: 010-9208-6514 | E20: S16796 | F20: 2420(부츠)sl (C) | G20: 아이보리(숏S) | H20: 12000 | K20: 1 | O20: 0 | R20: 8/21 더안불량(오염) | S20: 0 | T20: 0 | W20: （주）디투어패럴
A21: 리마인드 | B21: 경기도 고양시 일산동구 지영로 59-2 D동 | C21: 010-3918-2418 | D21: 010-9208-6514 | E21: S22136 | F21: 4503 [반바지] | G21: 블랙/S | H21: 10000 | K21: 1 | O21: 0 | R21: 8/18 더안불량(양쪽길이 다름) | S21: 0 | T21: 0 | W21: （주）디투어패럴
A22: 리마인드 | B22: 경기도 고양시 일산동구 지영로 59-2 D동 | C22: 010-3918-2418 | D22: 010-9208-6514 | E22: S22131 | F22: 4503 [반바지] | G22: 아이보리/M | H22: 10000 | K22: 1 | O22: 0 | R22: 8/18 더안불량(오염) | S22: 0 | T22: 0 | W22: （주）디투어패럴
A23: 리마인드 | B23: 경기도 고양시 일산동구 지영로 59-2 D동 | C23: 010-3918-2418 | D23: 010-9208-6514 | E23: S19666 | F23: 5100-3pt [부츠컷] | G23: 연청/M | H23: 14000 | K23: 1 | O23: 0 | R23: 8/6 더안불량(오입고) | S23: 0 | T23: 0 | W23: （주）디투어패럴
A24: 리마인드 | B24: 경기도 고양시 일산동구 지영로 59-2 D동 | C24: 010-3918-2418 | D24: 010-9208-6514 | E24: S19241 | F24: 5106-5pt [와이드] | G24: 화이트(S,롱) | H24: 13000 | K24: 1 | O24: 0 | R24: 8/18 더안불량(오염) | S24: 0 | T24: 0 | W24: （주）디투어패럴
A25: 리마인드 | B25: 경기도 고양시 일산동구 지영로 59-2 D동 | C25: 010-3918-2418 | D25: 010-9208-6514 | E25: S19240 | F25: 5106-5pt [와이드] | G25: 화이트(S,숏) | H25: 13000 | K25: 1 | O25: 0 | R25: 8/18 더안불량(오염) | S25: 0 | T25: 0 | W25: （주）디투어패럴
A26: 리마인드 | B26: 경기도 고양시 일산동구 지영로 59-2 D동 | C26: 010-3918-2418 | D26: 010-9208-6514 | E26: S22018 | F26: 5412nt [반팔] | G26: 베이지 | H26: 11000 | K26: 1 | O26: 0 | R26: 8/14 더안불량(앞면 오염) | S26: 0 | T26: 0 | W26: （주）디투어패럴
A27: 리마인드 | B27: 경기도 고양시 일산동구 지영로 59-2 D동 | C27: 010-3918-2418 | D27: 010-9208-6514 | F27: 8/25착오송금매입 | O27: 0 | T27: -17000 | W27: （주）디투어패럴
O28: 0 | S28: 0 | T28: 0
A29: KDG(부가세) | B29: 경기도 용인시 처인구 포곡읍 둔전로 49 | C29: 010-5818-0264 | D29: 010-5818-0264 | E29: S22534 | F29: 4081-1pt [부츠컷] | G29: 흑청/M/기본 | H29: 12500 | I29: 1 | L29: 1 | O29: 1 | S29: 1 | T29: 12500 | W29: 케이디지
A30: KDG(부가세) | B30: 경기도 용인시 처인구 포곡읍 둔전로 49 | C30: 010-5818-0264 | D30: 010-5818-0264 | E30: S22531 | F30: 4081-1pt [부츠컷] | G30: 흑청/S/기본 | H30: 12500 | I30: 1 | L30: 1 | O30: 1 | S30: 1 | T30: 12500 | W30: 케이디지
A31: KDG(부가세) | B31: 경기도 용인시 처인구 포곡읍 둔전로 49 | C31: 010-5818-0264 | D31: 010-5818-0264 | O31: 0 | R31: 08/26 부가세 | S31: 0 | T31: 2500 | W31: 케이디지
O32: 0 | S32: 0 | T32: 0
A33: 예삐박스 | B33: 남평화 3층 136 | C33: 010-5778-9084 | D33: 010-5778-9084 | E33: S22471 | F33: 여신하트라인골지캡소매티 [캡소매] | G33: 블랙 | H33: 6000 | I33: 1 | L33: 1 | O33: 1 | S33: 1 | T33: 6000 | W33: 김민
A34: 예삐박스 | B34: 남평화 3층 136 | C34: 010-5778-9084 | D34: 010-5778-9084 | E34: S22470 | F34: 여신하트라인골지캡소매티 [캡소매] | G34: 화이트 | H34: 6000 | I34: 1 | O34: 0 | Q34: 화밤 | S34: 0 | T34: 0 | W34: 김민
O35: 0 | S35: 0 | T35: 0
A36: 리머블 | B36: 남평화 지하 1층 B-14 | C36: 010-7761-8021 | D36: 010-7761-8021 | E36: S22867 | F36: 8900 [가방] | G36: 화이트 | H36: 13000 | I36: 1 | L36: 1 | O36: 1 | S36: 1 | T36: 13000 | W36: 정자영(리머블)
A37: 리머블 | B37: 남평화 지하 1층 B-14 | C37: 010-7761-8021 | D37: 010-7761-8021 | F37: 8/25착오송금매입 | O37: 0 | T37: -13000 | W37: 정자영(리머블)
O38: 0 | S38: 0 | T38: 0
A39: 언니제이 | B39: 누죤 1층 517 | C39: 010-7546-5171 | D39: 010-7546-5171 | E39: S22607 | F39: 1160밀키코튼블라우스 [반팔] | G39: 소라 ☆2508 | H39: 11000 | J39: 1 | M39: 1 | O39: 1 | R39: 미송1 | S39: 1 | T39: 0 | U39: 11000 | V39: 45889 | W39: 고연정
O40: 0 | S40: 0 | T40: 0
...

Sheet 0824
A1: 가나다란 08/24(일밤) 주문서 | I1: 발주 | L1: 장끼 | O1: 입고 | P1: 차이
A2: 거래처명 | B2: 공급처주소 | C2: 공급처연락처 | D2: 공급처휴대전화 | E2: 상품코드 | F2: 공급처상품명 | G2: 공급처옵션 | H2: 원가 | I2: 신규주문 | J2: 미송 | K2: 교환 | L2: 장끼 | M2: 미송 | N2: 교환 | O2: 주문 | P2: 주문 | Q2: 삼촌 코멘트 | R2: 가나다란 코멘트 | S2: 실입고수 | T2: 오늘입금할금액 | U2: 미송/매입금액 | V2: 입금일 | W2: 공급처예금주
I3: 3184 | J3: 565 | K3: 104 | L3: 960 | M3: 73 | N3: 23 | O3: 1131 | P3: 0 | Q3: 0 | R3: 0 | S3: 1116 | T3: 30134900 | U3: 7338000 | V3: 2707377
Q4: ※ 주문서 작성시 KDG, 제이와이엠, 디피프로젝트 카톡 채널 공유 필수 | S4: 0 | T4: 0
A5: 래래 | B5: 본사반출 | E5: S23304 | F5: 벨트sl | G5: 진베이지/s/롱 | K5: 1 | R5: 08/19 본사반출(코디, 촬영용 - 결제 완료) | S5: 0 | T5: 0 | W5: 김래영（래래（ＲＡＥ
A6: 래래 | B6: 본사반출 | E6: S23312 | F6: 벨트sl | G6: 블랙/s/롱 | K6: 1 | R6: 08/19 본사반출(코디, 촬영용 - 결제 완료) | S6: 0 | T6: 0 | W6: 김래영（래래（ＲＡＥ
A7: 래래 | B7: 본사반출 | E7: S23300 | F7: 벨트sl | G7: 아이/s/롱 | K7: 1 | R7: 08/19 본사반출(코디, 촬영용 - 결제 완료) | S7: 0 | T7: 0 | W7: 김래영（래래（ＲＡＥ
A8: 래래 | B8: 본사반출 | E8: S23308 | F8: 벨트sl | G8: 진그레이/s/롱 | K8: 1 | R8: 08/19 본사반출(코디, 촬영용 - 결제 완료) | S8: 0 | T8: 0 | W8: 김래영（래래（ＲＡＥ
A9: 래래 | B9: 본사반출 | E9: S23316 | F9: 벨트sl | G9: 브라운/s/롱 | K9: 1 | R9: 08/19 본사반출(코디, 촬영용 - 결제 완료) | S9: 0 | T9: 0 | W9: 김래영（래래（ＲＡＥ
S10: 0 | T10: 0
A11: 리마인드 | B11: 경기도 고양시 일산동구 지영로 59-2 D동 | C11: 010-3918-2418 | D11: 010-9208-6514 | E11: S16821 | F11: 2420(부츠)sl (C) | G11: 밤색(롱M) | H11: 12000 | I11: 1 | L11: 1 | O11: 1 | S11: 1 | T11: 12000 | W11: （주）디투어패럴
A12: 리마인드 | B12: 경기도 고양시 일산동구 지영로 59-2 D동 | C12: 010-3918-2418 | D12: 010-9208-6514 | E12: S16808 | F12: 2420(부츠)sl (C) | G12: 베이지(기본S) | H12: 12000 | I12: 1 | L12: 1 | O12: 1 | S12: 1 | T12: 12000 | W12: （주）디투어패럴
A13: 리마인드 | B13: 경기도 고양시 일산동구 지영로 59-2 D동 | C13: 010-3918-2418 | D13: 010-9208-6514 | E13: S16840 | F13: 2420(부츠)sl (C) | G13: 블랙(롱L) | H13: 12000 | I13: 2 | L13: 2 | O13: 2 | S13: 2 | T13: 24000 | W13: （주）디투어패럴
A14: 리마인드 | B14: 경기도 고양시 일산동구 지영로 59-2 D동 | C14: 010-3918-2418 | D14: 010-9208-6514 | E14: S16839 | F14: 2420(부츠)sl (C) | G14: 블랙(롱M) | H14: 12000 | I14: 5 | L14: 5 | O14: 5 | S14: 5 | T14: 60000 | W14: （주）디투어패럴
A15: 리마인드 | B15: 경기도 고양시 일산동구 지영로 59-2 D동 | C15: 010-3918-2418 | D15: 010-9208-6514 | E15: S16838 | F15: 2420(부츠)sl (C) | G15: 블랙(롱S) | H15: 12000 | I15: 5 | L15: 5 | O15: 5 | S15: 5 | T15: 60000 | W15: （주）디투어패럴
A16: 리마인드 | B16: 경기도 고양시 일산동구 지영로 59-2 D동 | C16: 010-3918-2418 | D16: 010-9208-6514 | E16: S16802 | F16: 2420(부츠)sl (C) | G16: 아이보리(롱S) | H16: 12000 | I16: 1 | L16: 1 | O16: 1 | S16: 1 | T16: 12000 | W16: （주）디투어패럴
A17: 리마인드 | B17: 경기도 고양시 일산동구 지영로 59-2 D동 | C17: 010-3918-2418 | D17: 010-9208-6514 | E17: S16826 | F17: 2420(부츠)sl (C) | G17: 회색(기본S) | H17: 12000 | I17: 1 | L17: 1 | O17: 1 | S17: 1 | T17: 12000 | W17: （주）디투어패럴
A18: 리마인드 | B18: 경기도 고양시 일산동구 지영로 59-2 D동 | C18: 010-3918-2418 | D18: 010-9208-6514 | E18: S16824 | F18: 2420(부츠)sl (C) | G18: 회색(숏M) | H18: 12000 | I18: 1 | L18: 1 | O18: 1 | S18: 1 | T18: 12000 | W18: （주）디투어패럴
A19: 리마인드 | B19: 경기도 고양시 일산동구 지영로 59-2 D동 | C19: 010-3918-2418 | D19: 010-9208-6514 | E19: S22134 | F19: 4503 [반바지] | G19: 베이지/M | H19: 10000 | I19: 1 | L19: 1 | O19: 1 | S19: 1 | T19: 10000 | W19: （주）디투어패럴
A20: 리마인드 | B20: 경기도 고양시 일산동구 지영로 59-2 D동 | C20: 010-3918-2418 | D20: 010-9208-6514 | E20: S18814 | F20: 5007pt [부츠컷] | G20: 중청(L) | H20: 15000 | I20: 1 | L20: 1 | O20: 1 | S20: 1 | T20: 15000 | W20: （주）디투어패럴
A21: 리마인드 | B21: 경기도 고양시 일산동구 지영로 59-2 D동 | C21: 010-3918-2418 | D21: 010-9208-6514 | E21: S19667 | F21: 5100-3pt [부츠컷] | G21: 연청/L | H21: 14000 | I21: 1 | L21: 1 | O21: 1 | S21: 1 | T21: 14000 | W21: （주）디투어패럴
A22: 리마인드 | B22: 경기도 고양시 일산동구 지영로 59-2 D동 | C22: 010-3918-2418 | D22: 010-9208-6514 | E22: S19243 | F22: 5106-5pt [와이드] | G22: 화이트(M,롱) | H22: 13000 | I22: 2 | L22: 2 | O22: 2 | S22: 2 | T22: 26000 | W22: （주）디투어패럴
A23: 리마인드 | B23: 경기도 고양시 일산동구 지영로 59-2 D동 | C23: 010-3918-2418 | D23: 010-9208-6514 | E23: S22020 | F23: 5412nt [반팔] | G23: 화이트 | H23: 9000 | I23: 2 | L23: 2 | O23: 2 | S23: 2 | T23: 18000 | W23: （주）디투어패럴
A24: 리마인드 | B24: 경기도 고양시 일산동구 지영로 59-2 D동 | C24: 010-3918-2418 | D24: 010-9208-6514 | E24: S16811 | F24: 2420(부츠)sl (C) | G24: 베이지(롱S) | H24: 12000 | K24: 1 | O24: 0 | R24: 8/21 더안불량(오염) | S24: 0 | T24: 0 | W24: （주）디투어패럴
A25: 리마인드 | B25: 경기도 고양시 일산동구 지영로 59-2 D동 | C25: 010-3918-2418 | D25: 010-9208-6514 | E25: S16800 | F25: 2420(부츠)sl (C) | G25: 아이보리(기본M) | H25: 12000 | K25: 1 | O25: 0 | R25: 8/13 더안불량(오염) | S25: 0 | T25: 0 | W25: （주）디투어패럴
A26: 리마인드 | B26: 경기도 고양시 일산동구 지영로 59-2 D동 | C26: 010-3918-2418 | D26: 010-9208-6514 | E26: S16796 | F26: 2420(부츠)sl (C) | G26: 아이보리(숏S) | H26: 12000 | K26: 1 | O26: 0 | R26: 8/21 더안불량(오염) | S26: 0 | T26: 0 | W26: （주）디투어패럴
A27: 리마인드 | B27: 경기도 고양시 일산동구 지영로 59-2 D동 | C27: 010-3918-2418 | D27: 010-9208-6514 | E27: S22136 | F27: 4503 [반바지] | G27: 블랙/S | H27: 10000 | K27: 1 | O27: 0 | R27: 8/18 더안불량(양쪽길이 다름) | S27: 0 | T27: 0 | W27: （주）디투어패럴
A28: 리마인드 | B28: 경기도 고양시 일산동구 지영로 59-2 D동 | C28: 010-3918-2418 | D28: 010-9208-6514 | E28: S22131 | F28: 4503 [반바지] | G28: 아이보리/M | H28: 10000 | K28: 1 | O28: 0 | R28: 8/18 더안불량(오염) | S28: 0 | T28: 0 | W28: （주）디투어패럴
A29: 리마인드 | B29: 경기도 고양시 일산동구 지영로 59-2 D동 | C29: 010-3918-2418 | D29: 010-9208-6514 | E29: S19666 | F29: 5100-3pt [부츠컷] | G29: 연청/M | H29: 14000 | K29: 1 | O29: 0 | R29: 8/6 더안불량(오입고) | S29: 0 | T29: 0 | W29: （주）디투어패럴
A30: 리마인드 | B30: 경기도 고양시 일산동구 지영로 59-2 D동 | C30: 010-3918-2418 | D30: 010-9208-6514 | E30: S19241 | F30: 5106-5pt [와이드] | G30: 화이트(S,롱) | H30: 13000 | K30: 1 | O30: 0 | R30: 8/18 더안불량(오염) | S30: 0 | T30: 0 | W30: （주）디투어패럴
A31: 리마인드 | B31: 경기도 고양시 일산동구 지영로 59-2 D동 | C31: 010-3918-2418 | D31: 010-9208-6514 | E31: S19240 | F31: 5106-5pt [와이드] | G31: 화이트(S,숏) | H31: 13000 | K31: 1 | O31: 0 | R31: 8/18 더안불량(오염) | S31: 0 | T31: 0 | W31: （주）디투어패럴
A32: 리마인드 | B32: 경기도 고양시 일산동구 지영로 59-2 D동 | C32: 010-3918-2418 | D32: 010-9208-6514 | E32: S22018 | F32: 5412nt [반팔] | G32: 베이지 | H32: 11000 | K32: 1 | O32: 0 | R32: 8/14 더안불량(앞면 오염) | S32: 0 | T32: 0 | W32: （주）디투어패럴
O33: 0 | S33: 0 | T33: 0
A34: 예삐박스 | B34: 남평화 3층 136 | C34: 010-5778-9084 | D34: 010-5778-9084 | E34: S22471 | F34: 여신하트라인골지캡소매티 [캡소매] | G34: 블랙 | H34: 6000 | I34: 2 | L34: 2 | O34: 2 | S34: 2 | T34: 12000 | W34: 김민
O35: 0 | S35: 0 | T35: 0
A36: 리머블 | B36: 남평화 지하 1층 B-14 | C36: 010-7761-8021 | D36: 010-7761-8021 | E36: S22866 | F36: 8900 [가방] | G36: 블랙 | H36: 13000 | I36: 1 | L36: 1 | O36: 1 | S36: 1 | T36: 13000 | W36: 정자영(리머블)
O37: 0 | S37: 0 | T37: 0
A38: 언니제이 | B38: 누죤 1층 517 | C38: 010-7546-5171 | D38: 010-7546-5171 | E38: S22607 | F38: 1160밀키코튼블라우스 [반팔] | G38: 소라 ☆2508 | H38: 11000 | J38: 1 | O38: 0 | Q38: 월밤 | R38: 미송1 | S38: 0 | T38: 0 | U38: 11000 | V38: 45889 | W38: 고연정
O39: 0 | S39: 0 | T39: 0
A40: 슬로그(누죤) | B40: 누죤 3층 429 | C40: 010-8780-0823 | D40: 010-8780-0823 | E40: S20981 | F40: 네스v넥 [반팔] | G40: 검정 | H40: 14000 | I40: 2 | L40: 2 | O40: 2 | S40: 2 | T40: 28000 | W40: 윤상원
...

Sheet 0821
A1: 가나다란 08/21(목밤) 주문서 | I1: 발주 | L1: 장끼 | O1: 입고 | P1: 차이
A2: 거래처명 | B2: 공급처주소 | C2: 공급처연락처 | D2: 공급처휴대전화 | E2: 상품코드 | F2: 공급처상품명 | G2: 공급처옵션 | H2: 원가 | I2: 신규주문 | J2: 미송 | K2: 교환 | L2: 장끼 | M2: 미송 | N2: 교환 | O2: 주문 | P2: 주문 | Q2: 삼촌 코멘트 | R2: 가나다란 코멘트 | S2: 실입고수 | T2: 오늘입금할금액 | U2: 미송/매입금액 | V2: 입금일 | W2: 공급처예금주
I3: 1491 | J3: 773 | K3: 128 | L3: 730 | M3: 359 | N3: 10 | O3: 1099 | P3: 0 | S3: 1099 | T3: 10635300 | U3: 10703000 | V3: 3395502
Q4: ※ 주문서 작성시 KDG, 제이와이엠, 디피프로젝트 카톡 채널 공유 필수 | S4: 0 | T4: 0
A5: 래래 | B5: 본사반출 | E5: S23304 | F5: 벨트sl | G5: 진베이지/s/롱 | K5: 1 | R5: 08/19 본사반출(코디, 촬영용 - 결제 완료) | T5: 0 | W5: 김래영（래래（ＲＡＥ
A6: 래래 | B6: 본사반출 | E6: S23312 | F6: 벨트sl | G6: 블랙/s/롱 | K6: 1 | R6: 08/19 본사반출(코디, 촬영용 - 결제 완료) | T6: 0 | W6: 김래영（래래（ＲＡＥ
A7: 래래 | B7: 본사반출 | E7: S23300 | F7: 벨트sl | G7: 아이/s/롱 | K7: 1 | R7: 08/19 본사반출(코디, 촬영용 - 결제 완료) | T7: 0 | W7: 김래영（래래（ＲＡＥ
A8: 래래 | B8: 본사반출 | E8: S23308 | F8: 벨트sl | G8: 진그레이/s/롱 | K8: 1 | R8: 08/19 본사반출(코디, 촬영용 - 결제 완료) | T8: 0 | W8: 김래영（래래（ＲＡＥ
A9: 래래 | B9: 본사반출 | E9: S23316 | F9: 벨트sl | G9: 브라운/s/롱 | K9: 1 | R9: 08/19 본사반출(코디, 촬영용 - 결제 완료) | T9: 0 | W9: 김래영（래래（ＲＡＥ
T10: 0
A11: 리마인드 | B11: 경기도 고양시 일산동구 지영로 59-2 D동 | C11: 010-3918-2418 | D11: 010-9208-6514 | E11: S16808 | F11: 2420(부츠)sl (C) | G11: 베이지(기본S) | H11: 12000 | I11: 1 | L11: 1 | O11: 1 | S11: 1 | T11: 12000 | W11: （주）디투어패럴
A12: 리마인드 | B12: 경기도 고양시 일산동구 지영로 59-2 D동 | C12: 010-3918-2418 | D12: 010-9208-6514 | E12: S16811 | F12: 2420(부츠)sl (C) | G12: 베이지(롱S) | H12: 12000 | I12: 1 | L12: 1 | O12: 1 | S12: 1 | T12: 12000 | W12: （주）디투어패럴
A13: 리마인드 | B13: 경기도 고양시 일산동구 지영로 59-2 D동 | C13: 010-3918-2418 | D13: 010-9208-6514 | E13: S16837 | F13: 2420(부츠)sl (C) | G13: 블랙(기본L) | H13: 12000 | I13: 1 | L13: 1 | O13: 1 | S13: 1 | T13: 12000 | W13: （주）디투어패럴
A14: 리마인드 | B14: 경기도 고양시 일산동구 지영로 59-2 D동 | C14: 010-3918-2418 | D14: 010-9208-6514 | E14: S16836 | F14: 2420(부츠)sl (C) | G14: 블랙(기본M) | H14: 12000 | I14: 3 | L14: 3 | O14: 3 | S14: 3 | T14: 36000 | W14: （주）디투어패럴
A15: 리마인드 | B15: 경기도 고양시 일산동구 지영로 59-2 D동 | C15: 010-3918-2418 | D15: 010-9208-6514 | E15: S16835 | F15: 2420(부츠)sl (C) | G15: 블랙(기본S) | H15: 12000 | I15: 5 | L15: 5 | O15: 5 | S15: 5 | T15: 60000 | W15: （주）디투어패럴
A16: 리마인드 | B16: 경기도 고양시 일산동구 지영로 59-2 D동 | C16: 010-3918-2418 | D16: 010-9208-6514 | E16: S16796 | F16: 2420(부츠)sl (C) | G16: 아이보리(숏S) | H16: 12000 | I16: 1 | L16: 1 | O16: 1 | S16: 1 | T16: 12000 | W16: （주）디투어패럴
A17: 리마인드 | B17: 경기도 고양시 일산동구 지영로 59-2 D동 | C17: 010-3918-2418 | D17: 010-9208-6514 | E17: S16823 | F17: 2420(부츠)sl (C) | G17: 회색(숏S) | H17: 12000 | I17: 1 | L17: 1 | O17: 1 | S17: 1 | T17: 12000 | W17: （주）디투어패럴
A18: 리마인드 | B18: 경기도 고양시 일산동구 지영로 59-2 D동 | C18: 010-3918-2418 | D18: 010-9208-6514 | E18: S22138 | F18: 4503 [반바지] | G18: 블랙/L | H18: 10000 | I18: 1 | L18: 1 | O18: 1 | S18: 1 | T18: 10000 | W18: （주）디투어패럴
A19: 리마인드 | B19: 경기도 고양시 일산동구 지영로 59-2 D동 | C19: 010-3918-2418 | D19: 010-9208-6514 | E19: S22136 | F19: 4503 [반바지] | G19: 블랙/S | H19: 10000 | I19: 1 | L19: 1 | O19: 1 | S19: 1 | T19: 10000 | W19: （주）디투어패럴
A20: 리마인드 | B20: 경기도 고양시 일산동구 지영로 59-2 D동 | C20: 010-3918-2418 | D20: 010-9208-6514 | E20: S22130 | F20: 4503 [반바지] | G20: 아이보리/S | H20: 10000 | I20: 5 | L20: 5 | O20: 5 | S20: 5 | T20: 50000 | W20: （주）디투어패럴
A21: 리마인드 | B21: 경기도 고양시 일산동구 지영로 59-2 D동 | C21: 010-3918-2418 | D21: 010-9208-6514 | E21: S19665 | F21: 5100-3pt [부츠컷] | G21: 연청/S | H21: 14000 | I21: 1 | L21: 1 | O21: 1 | S21: 1 | T21: 14000 | W21: （주）디투어패럴
A22: 리마인드 | B22: 경기도 고양시 일산동구 지영로 59-2 D동 | C22: 010-3918-2418 | D22: 010-9208-6514 | E22: S19245 | F22: 5106-5pt [와이드] | G22: 화이트(L,롱) | H22: 13000 | I22: 1 | L22: 1 | O22: 1 | S22: 1 | T22: 13000 | W22: （주）디투어패럴
... A25: 리마인드 | B25: 경기도 고양시 일산동구 지영로 59-2 D동 | C25: 010-3918-2418 | D25: 010-9208-6514 | E25: S21623 | F25: 5507pt [와이드] | G25: 진청(5507-1)/M | H25: 16000 | I25: 1 | L25: 1 | O25: 1 | S25: 1 | T25: 16000 | W25: （주）디투어패럴
A26: 리마인드 | B26: 경기도 고양시 일산동구 지영로 59-2 D동 | C26: 010-3918-2418 | D26: 010-9208-6514 | E26: S16800 | F26: 2420(부츠)sl (C) | G26: 아이보리(기본M) | H26: 12000 | K26: 1 | O26: 0 | R26: 8/13 더안불량(오염) | S26: 0 | T26: 0 | W26: （주）디투어패럴
A27: 리마인드 | B27: 경기도 고양시 일산동구 지영로 59-2 D동 | C27: 010-3918-2418 | D27: 010-9208-6514 | E27: S22136 | F27: 4503 [반바지] | G27: 블랙/S | H27: 10000 | K27: 1 | O27: 0 | R27: 8/18 더안불량(양쪽길이 다름) | S27: 0 | T27: 0 | W27: （주）디투어패럴
A28: 리마인드 | B28: 경기도 고양시 일산동구 지영로 59-2 D동 | C28: 010-3918-2418 | D28: 010-9208-6514 | E28: S22131 | F28: 4503 [반바지] | G28: 아이보리/M | H28: 10000 | K28: 1 | O28: 0 | R28: 8/18 더안불량(오염) | S28: 0 | T28: 0 | W28: （주）디투어패럴
A29: 리마인드 | B29: 경기도 고양시 일산동구 지영로 59-2 D동 | C29: 010-3918-2418 | D29: 010-9208-6514 | E29: S19666 | F29: 5100-3pt [부츠컷] | G29: 연청/M | H29: 14000 | K29: 1 | O29: 0 | R29: 8/6 더안불량(오입고) | S29: 0 | T29: 0 | W29: （주）디투어패럴
A30: 리마인드 | B30: 경기도 고양시 일산동구 지영로 59-2 D동 | C30: 010-3918-2418 | D30: 010-9208-6514 | E30: S19241 | F30: 5106-5pt [와이드] | G30: 화이트(S,롱) | H30: 13000 | K30: 1 | O30: 0 | R30: 8/18 더안불량(오염) | S30: 0 | T30: 0 | W30: （주）디투어패럴
A31: 리마인드 | B31: 경기도 고양시 일산동구 지영로 59-2 D동 | C31: 010-3918-2418 | D31: 010-9208-6514 | E31: S19240 | F31: 5106-5pt [와이드] | G31: 화이트(S,숏) | H31: 13000 | K31: 1 | O31: 0 | R31: 8/18 더안불량(오염) | S31: 0 | T31: 0 | W31: （주）디투어패럴
A32: 리마인드 | B32: 경기도 고양시 일산동구 지영로 59-2 D동 | C32: 010-3918-2418 | D32: 010-9208-6514 | E32: S22018 | F32: 5412nt [반팔] | G32: 베이지 | H32: 11000 | K32: 1 | O32: 0 | R32: 8/14 더안불량(앞면 오염) | S32: 0 | T32: 0 | W32: （주）디투어패럴
A33: 리마인드 | B33: 경기도 고양시 일산동구 지영로 59-2 D동 | C33: 010-3918-2418 | D33: 010-9208-6514 | E33: S16811 | F33: 2420(부츠)sl (C) | G33: 베이지(롱S) | H33: 12000 | K33: 1 | O33: 0 | R33: 8/21 더안불량(오염) | S33: 0 | T33: 0 | W33: （주）디투어패럴
A34: 리마인드 | B34: 경기도 고양시 일산동구 지영로 59-2 D동 | C34: 010-3918-2418 | D34: 010-9208-6514 | E34: S16796 | F34: 2420(부츠)sl (C) | G34: 아이보리(숏S) | H34: 12000 | K34: 1 | O34: 0 | R34: 8/21 더안불량(오염) | S34: 0 | T34: 0 | W34: （주）디투어패럴
O35: 0 | S35: 0 | T35: 0
A36: KDG(부가세) | B36: 경기도 용인시 처인구 포곡읍 둔전로 49 | C36: 010-5818-0264 | D36: 010-5818-0264 | E36: S22536 | F36: 4081-1pt [부츠컷] | G36: 흑청/L/숏 | H36: 12500 | I36: 1 | L36: 1 | O36: 1 | S36: 1 | T36: 12500 | W36: 케이디지
A37: KDG(부가세) | B37: 경기도 용인시 처인구 포곡읍 둔전로 49 | C37: 010-5818-0264 | D37: 010-5818-0264 | E37: S22533 | F37: 4081-1pt [부츠컷] | G37: 흑청/M/숏 | H37: 12500 | I37: 1 | L37: 1 | O37: 1 | S37: 1 | T37: 12500 | W37: 케이디지
A38: KDG(부가세) | B38: 경기도 용인시 처인구 포곡읍 둔전로 49 | C38: 010-5818-0264 | D38: 010-5818-0264 | O38: 0 | R38: 08/22 부가세 | S38: 0 | T38: 2500 | W38: 케이디지
O39: 0 | S39: 0 | T39: 0
A40: 예삐박스 | B40: 남평화 3층 136 | C40: 010-5778-9084 | D40: 010-5778-9084 | E40: S22470 | F40: 여신하트라인골지캡소매티 [캡소매] | G40: 화이트 | H40: 6000 | I40: 1 | L40: 1 | O40: 1 | S40: 1 | T40: 6000 | W40: 김민
A41: 예삐박스 | B41: 남평화 3층 136 | C41: 010-5778-9084 | D41: 010-5778-9084 | E41: S22469 | F41: 여신하트라인골지캡소매티 [캡소매] | G41: 베이지 | H41: 6000 | K41: 1 | O41: 0 | Q41: 차감함 | R41: 8/19 더안불량(오염) | S41: 0 | T41: -6000 | W41: 김민
O42: 0 | S42: 0 | T42: 0
...

Sheet 0820
A1: 가나다란 08/20(수밤) 주문서 | I1: 발주 | L1: 장끼 | O1: 입고 | P1: 차이
A2: 거래처명 | B2: 공급처주소 | C2: 공급처연락처 | D2: 공급처휴대전화 | E2: 상품코드 | F2: 공급처상품명 | G2: 공급처옵션 | H2: 원가 | I2: 신규주문 | J2: 미송 | K2: 교환 | L2: 장끼 | M2: 미송 | N2: 교환 | O2: 주문 | P2: 주문 | Q2: 삼촌 코멘트 | R2: 가나다란 코멘트 | S2: 실입고수 | T2: 오늘입금할금액 | U2: 미송/매입금액 | V2: 입금일 | W2: 공급처예금주
I3: 1707 | J3: 800 | K3: 156 | L3: 829 | M3: 95 | N3: 16 | O3: 405 | P3: 0 | S3: 405 | T3: 15723900 | U3: 9829500 | V3: 3120107
Q4: ※ 주문서 작성시 KDG, 제이와이엠, 디피프로젝트 카톡 채널 공유 필수 | S4: 0 | T4: 0
A5: 래래 | B5: 본사반출 | E5: S23304 | F5: 벨트sl | G5: 진베이지/s/롱 | K5: 1 | R5: 08/19 본사반출(코디, 촬영용 - 결제 완료) | T5: 0 | W5: 김래영（래래（ＲＡＥ
A6: 래래 | B6: 본사반출 | E6: S23312 | F6: 벨트sl | G6: 블랙/s/롱 | K6: 1 | R6: 08/19 본사반출(코디, 촬영용 - 결제 완료) | T6: 0 | W6: 김래영（래래（ＲＡＥ
A7: 래래 | B7: 본사반출 | E7: S23300 | F7: 벨트sl | G7: 아이/s/롱 | K7: 1 | R7: 08/19 본사반출(코디, 촬영용 - 결제 완료) | T7: 0 | W7: 김래영（래래（ＲＡＥ
A8: 래래 | B8: 본사반출 | E8: S23308 | F8: 벨트sl | G8: 진그레이/s/롱 | K8: 1 | R8: 08/19 본사반출(코디, 촬영용 - 결제 완료) | T8: 0 | W8: 김래영（래래（ＲＡＥ
A9: 래래 | B9: 본사반출 | E9: S23316 | F9: 벨트sl | G9: 브라운/s/롱 | K9: 1 | R9: 08/19 본사반출(코디, 촬영용 - 결제 완료) | T9: 0 | W9: 김래영（래래（ＲＡＥ
T10: 0
A11: 리마인드 | B11: 경기도 고양시 일산동구 지영로 59-2 D동 | C11: 010-3918-2418 | D11: 010-9208-6514 | E11: S16811 | F11: 2420(부츠)sl (C) | G11: 베이지(롱S) | H11: 12000 | I11: 1 | L11: 1 | O11: 1 | S11: 1 | T11: 12000 | W11: （주）디투어패럴
A12: 리마인드 | B12: 경기도 고양시 일산동구 지영로 59-2 D동 | C12: 010-3918-2418 | D12: 010-9208-6514 | E12: S16837 | F12: 2420(부츠)sl (C) | G12: 블랙(기본L) | H12: 12000 | I12: 1 | L12: 1 | O12: 1 | S12: 1 | T12: 12000 | W12: （주）디투어패럴
A13: 리마인드 | B13: 경기도 고양시 일산동구 지영로 59-2 D동 | C13: 010-3918-2418 | D13: 010-9208-6514 | E13: S16836 | F13: 2420(부츠)sl (C) | G13: 블랙(기본M) | H13: 12000 | I13: 1 | L13: 1 | O13: 1 | S13: 1 | T13: 12000 | W13: （주）디투어패럴
A14: 리마인드 | B14: 경기도 고양시 일산동구 지영로 59-2 D동 | C14: 010-3918-2418 | D14: 010-9208-6514 | E14: S16835 | F14: 2420(부츠)sl (C) | G14: 블랙(기본S) | H14: 12000 | I14: 1 | L14: 1 | O14: 1 | S14: 1 | T14: 12000 | W14: （주）디투어패럴
A15: 리마인드 | B15: 경기도 고양시 일산동구 지영로 59-2 D동 | C15: 010-3918-2418 | D15: 010-9208-6514 | E15: S16802 | F15: 2420(부츠)sl (C) | G15: 아이보리(롱S) | H15: 12000 | I15: 1 | L15: 1 | O15: 1 | S15: 1 | T15: 12000 | W15: （주）디투어패럴
A16: 리마인드 | B16: 경기도 고양시 일산동구 지영로 59-2 D동 | C16: 010-3918-2418 | D16: 010-9208-6514 | E16: S16796 | F16: 2420(부츠)sl (C) | G16: 아이보리(숏S) | H16: 12000 | I16: 1 | L16: 1 | O16: 1 | S16: 1 | T16: 12000 | W16: （주）디투어패럴
A17: 리마인드 | B17: 경기도 고양시 일산동구 지영로 59-2 D동 | C17: 010-3918-2418 | D17: 010-9208-6514 | E17: S16864 | F17: 2430(와이드)sl ☆ | G17: 블랙(기본M) ☆2506 | H17: 12000 | I17: 1 | L17: 1 | O17: 1 | S17: 1 | T17: 12000 | W17: （주）디투어패럴
A18: 리마인드 | B18: 경기도 고양시 일산동구 지영로 59-2 D동 | C18: 010-3918-2418 | D18: 010-9208-6514 | E18: S22134 | F18: 4503 [반바지] | G18: 베이지/M | H18: 10000 | I18: 2 | L18: 2 | O18: 2 | S18: 2 | T18: 20000 | W18: （주）디투어패럴
A19: 리마인드 | B19: 경기도 고양시 일산동구 지영로 59-2 D동 | C19: 010-3918-2418 | D19: 010-9208-6514 | E19: S22137 | F19: 4503 [반바지] | G19: 블랙/M | H19: 10000 | I19: 5 | L19: 5 | O19: 5 | S19: 5 | T19: 50000 | W19: （주）디투어패럴
A20: 리마인드 | B20: 경기도 고양시 일산동구 지영로 59-2 D동 | C20: 010-3918-2418 | D20: 010-9208-6514 | E20: S22136 | F20: 4503 [반바지] | G20: 블랙/S | H20: 10000 | I20: 2 | L20: 2 | O20: 2 | S20: 2 | T20: 20000 | W20: （주）디투어패럴
A21: 리마인드 | B21: 경기도 고양시 일산동구 지영로 59-2 D동 | C21: 010-3918-2418 | D21: 010-9208-6514 | E21: S22131 | F21: 4503 [반바지] | G21: 아이보리/M | H21: 10000 | I21: 10 | L21: 10 | O21: 10 | S21: 10 | T21: 100000 | W21: （주）디투어패럴
A22: 리마인드 | B22: 경기도 고양시 일산동구 지영로 59-2 D동 | C22: 010-3918-2418 | D22: 010-9208-6514 | E22: S19665 | F22: 5100-3pt [부츠컷] | G22: 연청/S | H22: 14000 | I22: 1 | L22: 1 | O22: 1 | S22: 1 | T22: 14000 | W22: （주）디투어패럴
A23: 리마인드 | B23: 경기도 고양시 일산동구 지영로 59-2 D동 | C23: 010-3918-2418 | D23: 010-9208-6514 | E23: S22019 | F23: 5412nt [반팔] | G23: 블랙 | H23: 11000 | I23: 2 | L23: 2 | O23: 2 | S23: 2 | T23: 18000 | W23: （주）디투어패럴
A24: 리마인드 | B24: 경기도 고양시 일산동구 지영로 59-2 D동 | C24: 010-3918-2418 | D24: 010-9208-6514 | O24: 0 | Q24: 8/4 오더건 > 입금 필요 | S24: 0 | T24: 3562000 | W24: （주）디투어패럴
A25: 리마인드 | B25: 경기도 고양시 일산동구 지영로 59-2 D동 | C25: 010-3918-2418 | D25: 010-9208-6514 | E25: S16800 | F25: 2420(부츠)sl (C) | G25: 아이보리(기본M) | H25: 12000 | K25: 1 | O25: 0 | R25: 8/13 더안불량(오염) | S25: 0 | T25: 0 | W25: （주）디투어패럴
A26: 리마인드 | B26: 경기도 고양시 일산동구 지영로 59-2 D동 | C26: 010-3918-2418 | D26: 010-9208-6514 | E26: S22136 | F26: 4503 [반바지] | G26: 블랙/S | H26: 10000 | K26: 1 | O26: 0 | R26: 8/18 더안불량(양쪽길이 다름) | S26: 0 | T26: 0 | W26: （주）디투어패럴
A27: 리마인드 | B27: 경기도 고양시 일산동구 지영로 59-2 D동 | C27: 010-3918-2418 | D27: 010-9208-6514 | E27: S22131 | F27: 4503 [반바지] | G27: 아이보리/M | H27: 10000 | K27: 1 | O27: 0 | R27: 8/18 더안불량(오염) | S27: 0 | T27: 0 | W27: （주）디투어패럴
A28: 리마인드 | B28: 경기도 고양시 일산동구 지영로 59-2 D동 | C28: 010-3918-2418 | D28: 010-9208-6514 | E28: S19666 | F28: 5100-3pt [부츠컷] | G28: 연청/M | H28: 14000 | K28: 1 | O28: 0 | R28: 8/6 더안불량(오입고) | S28: 0 | T28: 0 | W28: （주）디투어패럴
A29: 리마인드 | B29: 경기도 고양시 일산동구 지영로 59-2 D동 | C29: 010-3918-2418 | D29: 010-9208-6514 | E29: S19241 | F29: 5106-5pt [와이드] | G29: 화이트(S,롱) | H29: 13000 | K29: 1 | O29: 0 | R29: 8/18 더안불량(오염) | S29: 0 | T29: 0 | W29: （주）디투어패럴
A30: 리마인드 | B30: 경기도 고양시 일산동구 지영로 59-2 D동 | C30: 010-3918-2418 | D30: 010-9208-6514 | E30: S19240 | F30: 5106-5pt [와이드] | G30: 화이트(S,숏) | H30: 13000 | K30: 1 | O30: 0 | R30: 8/18 더안불량(오염) | S30: 0 | T30: 0 | W30: （주）디투어패럴
A31: 리마인드 | B31: 경기도 고양시 일산동구 지영로 59-2 D동 | C31: 010-3918-2418 | D31: 010-9208-6514 | E31: S22018 | F31: 5412nt [반팔] | G31: 베이지 | H31: 11000 | K31: 1 | O31: 0 | R31: 8/14 더안불량(앞면 오염) | S31: 0 | T31: 0 | W31: （주）디투어패럴
A32: 리마인드 | B32: 경기도 고양시 일산동구 지영로 59-2 D동 | C32: 010-3918-2418 | D32: 010-9208-6514 | E32: S16796 | F32: 2420(부츠)sl (C) | G32: 아이보리(숏S) | H32: 12000 | K32: 1 | O32: 0 | R32: 8/21 더안불량(오염) | S32: 0 | T32: 0 | W32: （주）디투어패럴
A33: 리마인드 | B33: 경기도 고양시 일산동구 지영로 59-2 D동 | C33: 010-3918-2418 | D33: 010-9208-6514 | E33: S16811 | F33: 2420(부츠)sl (C) | G33: 베이지(롱S) | H33: 12000 | K33: 1 | O33: 0 | R33: 8/21 더안불량(오염) | S33: 0 | T33: 0 | W33: （주）디투어패럴
O34: 0 | S34: 0 | T34: 0
A35: 예삐박스 | B35: 남평화 3층 136 | C35: 010-5778-9084 | D35: 010-5778-9084 | E35: S22471 | F35: 여신하트라인골지캡소매티 [캡소매] | G35: 블랙 | H35: 6000 | I35: 1 | O35: 0 | Q35: 목밤 | S35: 0 | T35: 0 | W35: 김민
A36: 예삐박스 | B36: 남평화 3층 136 | C36: 010-5778-9084 | D36: 010-5778-9084 | E36: S22469 | F36: 여신하트라인골지캡소매티 [캡소매] | G36: 베이지 | H36: 6000 | K36: 1 | O36: 0 | Q36: 목밤 | R36: 8/19 더안불량(오염) | S36: 0 | T36: 0 | W36: 김민
O37: 0 | S37: 0 | T37: 0
A38: 리머블 | B38: 남평화 지하 1층 B-14 | C38: 010-7761-8021 | D38: 010-7761-8021 | E38: S22866 | F38: 8900 [가방] | G38: 블랙 | H38: 13000 | I38: 1 | L38: 1 | O38: 1 | S38: 1 | T38: 13000 | W38: 정자영(리머블)
A39: 리머블 | B39: 남평화 지하 1층 B-14 | C39: 010-7761-8021 | D39: 010-7761-8021 | E39: S22867 | F39: 8900 [가방] | G39: 화이트 | H39: 13000 | I39: 2 | O39: 0 | Q39: 목밤 | S39: 0 | T39: 0 | W39: 정자영(리머블)
O40: 0 | S40: 0 | T40: 0
...

Sheet 0819
A1: 가나다란 08/19(화밤) 주문서 | I1: 발주 | L1: 장끼 | O1: 입고 | P1: 차이
A2: 거래처명 | B2: 공급처주소 | C2: 공급처연락처 | D2: 공급처휴대전화 | E2: 상품코드 | F2: 공급처상품명 | G2: 공급처옵션 | H2: 원가 | I2: 신규주문 | J2: 미송 | K2: 교환 | L2: 장끼 | M2: 미송 | N2: 교환 | O2: 주문 | P2: 주문 | Q2: 삼촌 코멘트 | R2: 가나다란 코멘트 | S2: 실입고수 | T2: 오늘입금할금액 | U2: 미송/매입금액 | V2: 입금일 | W2: 공급처예금주
I3: 1373 | J3: 1002 | K3: 158 | L3: 581 | M3: 244 | N3: 12 | O3: 837 | P3: 0 | S3: 837 | T3: 8431600 | U3: 13292500 | V3: 0
Q4: ※ 주문서 작성시 KDG, 제이와이엠, 디피프로젝트 카톡 채널 공유 필수 | S4: 0 | T4: 0
A5: 래래 | B5: 본사반출 | E5: S23304 | F5: 벨트sl | G5: 진베이지/s/롱 | K5: 1 | R5: 08/19 본사반출(코디, 촬영용 - 결제 완료) | S5: 0 | T5: 0 | W5: 김래영（래래（ＲＡＥ
A6: 래래 | B6: 본사반출 | E6: S23312 | F6: 벨트sl | G6: 블랙/s/롱 | K6: 1 | R6: 08/19 본사반출(코디, 촬영용 - 결제 완료) | S6: 0 | T6: 0 | W6: 김래영（래래（ＲＡＥ
A7: 래래 | B7: 본사반출 | E7: S23300 | F7: 벨트sl | G7: 아이/s/롱 | K7: 1 | R7: 08/19 본사반출(코디, 촬영용 - 결제 완료) | S7: 0 | T7: 0 | W7: 김래영（래래（ＲＡＥ
A8: 래래 | B8: 본사반출 | E8: S23308 | F8: 벨트sl | G8: 진그레이/s/롱 | K8: 1 | R8: 08/19 본사반출(코디, 촬영용 - 결제 완료) | S8: 0 | T8: 0 | W8: 김래영（래래（ＲＡＥ
A9: 래래 | B9: 본사반출 | E9: S23316 | F9: 벨트sl | G9: 브라운/s/롱 | K9: 1 | R9: 08/19 본사반출(코디, 촬영용 - 결제 완료) | S9: 0 | T9: 0 | W9: 김래영（래래（ＲＡＥ
A10: 라온 | B10: 본사보유입고 | E10: S22778 | F10: gn01 (벨트X) | G10: 그레이/롱/S | K10: 1 | R10: 08/19 본사보유입고 | S10: 0 | T10: 0 | W10: 박맹길（라온（ＲＡＯ
A11: 라온 | B11: 본사보유입고 | E11: S22772 | F11: gn01 (벨트X) | G11: 블랙/롱/S | K11: 1 | R11: 08/19 본사보유입고 | S11: 0 | T11: 0 | W11: 박맹길（라온（ＲＡＯ
A12: 라온 | B12: 본사보유입고 | E12: S21682 | F12: gn02 (벨트x) | G12: 베이지/롱/S | K12: 1 | R12: 08/19 본사보유입고 | S12: 0 | T12: 0 | W12: 박맹길（라온（ＲＡＯ
A13: 라온 | B13: 본사보유입고 | E13: S21688 | F13: gn02 (벨트x) | G13: 블랙/롱/S | K13: 1 | R13: 08/19 본사보유입고 | S13: 0 | T13: 0 | W13: 박맹길（라온（ＲＡＯ
A14: 라라랜드 | B14: 본사보유입고 | E14: S22068 | F14: 가나다란찰랑와이드 | G14: 베이지/롱/S | K14: 1 | R14: 08/19 본사보유입고 | S14: 0 | T14: 0 | W14: 정지숙
A15: 라라랜드 | B15: 본사보유입고 | E15: S22074 | F15: 가나다란찰랑와이드 | G15: 블랙/롱/S | K15: 1 | R15: 08/19 본사보유입고 | S15: 0 | T15: 0 | W15: 정지숙
A16: 라라랜드 | B16: 본사보유입고 | E16: S21366 | F16: 가나다란무크와이드 | G16: 크림/기본/S | K16: 1 | R16: 08/19 본사보유입고 | S16: 0 | T16: 0 | W16: 정지숙
... A18: 라라랜드 | B18: 본사보유입고 | E18: S21361 | F18: 가나다란무크와이드 | G18: 블랙/롱/S | K18: 1 | R18: 08/19 본사보유입고 | S18: 0 | T18: 0 | W18: 정지숙
T19: 0
A20: 리마인드 | B20: 경기도 고양시 일산동구 지영로 59-2 D동 | C20: 010-3918-2418 | D20: 010-9208-6514 | E20: S16837 | F20: 2420(부츠)sl (C) | G20: 블랙(기본L) | H20: 12000 | I20: 1 | L20: 1 | O20: 1 | S20: 1 | T20: 12000 | W20: （주）디투어패럴
A21: 리마인드 | B21: 경기도 고양시 일산동구 지영로 59-2 D동 | C21: 010-3918-2418 | D21: 010-9208-6514 | E21: S16836 | F21: 2420(부츠)sl (C) | G21: 블랙(기본M) | H21: 12000 | I21: 1 | L21: 1 | O21: 1 | S21: 1 | T21: 12000 | W21: （주）디투어패럴
A22: 리마인드 | B22: 경기도 고양시 일산동구 지영로 59-2 D동 | C22: 010-3918-2418 | D22: 010-9208-6514 | E22: S16835 | F22: 2420(부츠)sl (C) | G22: 블랙(기본S) | H22: 12000 | I22: 1 | L22: 1 | O22: 1 | S22: 1 | T22: 12000 | W22: （주）디투어패럴
A23: 리마인드 | B23: 경기도 고양시 일산동구 지영로 59-2 D동 | C23: 010-3918-2418 | D23: 010-9208-6514 | E23: S16840 | F23: 2420(부츠)sl (C) | G23: 블랙(롱L) | H23: 12000 | I23: 1 | L23: 1 | O23: 1 | S23: 1 | T23: 12000 | W23: （주）디투어패럴
A24: 리마인드 | B24: 경기도 고양시 일산동구 지영로 59-2 D동 | C24: 010-3918-2418 | D24: 010-9208-6514 | E24: S16839 | F24: 2420(부츠)sl (C) | G24: 블랙(롱M) | H24: 12000 | I24: 1 | L24: 1 | O24: 1 | S24: 1 | T24: 12000 | W24: （주）디투어패럴
A25: 리마인드 | B25: 경기도 고양시 일산동구 지영로 59-2 D동 | C25: 010-3918-2418 | D25: 010-9208-6514 | E25: S16834 | F25: 2420(부츠)sl (C) | G25: 블랙(숏L) | H25: 12000 | I25: 1 | L25: 1 | O25: 1 | S25: 1 | T25: 12000 | W25: （주）디투어패럴
A26: 리마인드 | B26: 경기도 고양시 일산동구 지영로 59-2 D동 | C26: 010-3918-2418 | D26: 010-9208-6514 | E26: S16832 | F26: 2420(부츠)sl (C) | G26: 블랙(숏S) | H26: 12000 | I26: 3 | L26: 3 | O26: 3 | S26: 3 | T26: 36000 | W26: （주）디투어패럴
A27: 리마인드 | B27: 경기도 고양시 일산동구 지영로 59-2 D동 | C27: 010-3918-2418 | D27: 010-9208-6514 | E27: S16828 | F27: 2420(부츠)sl (C) | G27: 회색(기본L) | H27: 12000 | I27: 1 | L27: 1 | O27: 1 | S27: 1 | T27: 12000 | W27: （주）디투어패럴
A28: 리마인드 | B28: 경기도 고양시 일산동구 지영로 59-2 D동 | C28: 010-3918-2418 | D28: 010-9208-6514 | E28: S16826 | F28: 2420(부츠)sl (C) | G28: 회색(기본S) | H28: 12000 | I28: 1 | L28: 1 | O28: 1 | S28: 1 | T28: 12000 | W28: （주）디투어패럴
A29: 리마인드 | B29: 경기도 고양시 일산동구 지영로 59-2 D동 | C29: 010-3918-2418 | D29: 010-9208-6514 | E29: S22138 | F29: 4503 [반바지] | G29: 블랙/L | H29: 10000 | I29: 1 | L29: 1 | O29: 1 | S29: 1 | T29: 10000 | W29: （주）디투어패럴
A30: 리마인드 | B30: 경기도 고양시 일산동구 지영로 59-2 D동 | C30: 010-3918-2418 | D30: 010-9208-6514 | E30: S19244 | F30: 5106-5pt [와이드] | G30: 화이트(L,숏) | H30: 13000 | I30: 1 | L30: 1 | O30: 1 | S30: 1 | T30: 13000 | W30: （주）디투어패럴
A31: 리마인드 | B31: 경기도 고양시 일산동구 지영로 59-2 D동 | C31: 010-3918-2418 | D31: 010-9208-6514 | E31: S19243 | F31: 5106-5pt [와이드] | G31: 화이트(M,롱) | H31: 13000 | I31: 3 | L31: 3 | O31: 3 | S31: 3 | T31: 39000 | W31: （주）디투어패럴
... A34: 리마인드 | B34: 경기도 고양시 일산동구 지영로 59-2 D동 | C34: 010-3918-2418 | D34: 010-9208-6514 | E34: S21623 | F34: 5507pt [와이드] | G34: 진청(5507-1)/M | H34: 16000 | I34: 1 | L34: 1 | O34: 1 | S34: 1 | T34: 16000 | W34: （주）디투어패럴
A35: 리마인드 | B35: 경기도 고양시 일산동구 지영로 59-2 D동 | C35: 010-3918-2418 | D35: 010-9208-6514 | E35: S20240 | F35: gn-001 [부츠컷] ☆ | G35: 블랙/M ♡(사이즈별 300장) | H35: 12500 | I35: 5 | O35: 0 | S35: 0 | T35: 0 | W35: （주）디투어패럴
A36: 리마인드 | B36: 경기도 고양시 일산동구 지영로 59-2 D동 | C36: 010-3918-2418 | D36: 010-9208-6514 | E36: S20074 | F36: gn-001 [부츠컷] ☆ | G36: 블랙/S ♡(사이즈별 300장) | H36: 12500 | I36: 5 | O36: 0 | S36: 0 | T36: 0 | W36: （주）디투어패럴
A37: 리마인드 | B37: 경기도 고양시 일산동구 지영로 59-2 D동 | C37: 010-3918-2418 | D37: ` | E37: S16800 | F37: 2420(부츠)sl (C) | G37: 아이보리(기본M) | H37: 12000 | K37: 1 | O37: 0 | R37: 8/13 더안불량(오염) | S37: 0 | T37: 0 | W37: （주）디투어패럴
A38: 리마인드 | B38: 경기도 고양시 일산동구 지영로 59-2 D동 | C38: 010-3918-2418 | D38: 010-9208-6514 | E38: S22136 | F38: 4503 [반바지] | G38: 블랙/S | H38: 10000 | K38: 1 | O38: 0 | R38: 8/18 더안불량(양쪽길이 다름) | S38: 0 | T38: 0 | W38: （주）디투어패럴
A39: 리마인드 | B39: 경기도 고양시 일산동구 지영로 59-2 D동 | C39: 010-3918-2418 | D39: 010-9208-6514 | E39: S22131 | F39: 4503 [반바지] | G39: 아이보리/M | H39: 10000 | K39: 1 | O39: 0 | R39: 8/18 더안불량(오염) | S39: 0 | T39: 0 | W39: （주）디투어패럴
A40: 리마인드 | B40: 경기도 고양시 일산동구 지영로 59-2 D동 | C40: 010-3918-2418 | D40: 010-9208-6514 | E40: S19666 | F40: 5100-3pt [부츠컷] | G40: 연청/M | H40: 14000 | K40: 1 | O40: 0 | R40: 8/6 더안불량(오입고) | S40: 0 | T40: 0 | W40: （주）디투어패럴
A41: 리마인드 | B41: 경기도 고양시 일산동구 지영로 59-2 D동 | C41: 010-3918-2418 | D41: 010-9208-6514 | E41: S19241 | F41: 5106-5pt [와이드] | G41: 화이트(S,롱) | H41: 13000 | K41: 1 | O41: 0 | R41: 8/18 더안불량(오염) | S41: 0 | T41: 0 | W41: （주）디투어패럴
A42: 리마인드 | B42: 경기도 고양시 일산동구 지영로 59-2 D동 | C42: 010-3918-2418 | D42: 010-9208-6514 | E42: S19240 | F42: 5106-5pt [와이드] | G42: 화이트(S,숏) | H42: 13000 | K42: 1 | O42: 0 | R42: 8/18 더안불량(오염) | S42: 0 | T42: 0 | W42: （주）디투어패럴
A43: 리마인드 | B43: 경기도 고양시 일산동구 지영로 59-2 D동 | C43: 010-3918-2418 | D43: 010-9208-6514 | E43: S22018 | F43: 5412nt [반팔] | G43: 베이지 | H43: 11000 | K43: 1 | O43: 0 | R43: 8/14 더안불량(앞면 오염) | S43: 0 | T43: 0 | W43: （주）디투어패럴
...

Sheet 0818
A1: 가나다란 08/18(월밤) 주문서 | I1: 발주 | L1: 장끼 | O1: 입고 | P1: 차이
A2: 거래처명 | B2: 공급처주소 | C2: 공급처연락처 | D2: 공급처휴대전화 | E2: 상품코드 | F2: 공급처상품명 | G2: 공급처옵션 | H2: 원가 | I2: 신규주문 | J2: 미송 | K2: 교환 | L2: 장끼 | M2: 미송 | N2: 교환 | O2: 주문 | P2: 주문 | Q2: 삼촌 코멘트 | R2: 가나다란 코멘트 | S2: 실입고수 | T2: 오늘입금할금액 | U2: 미송/매입금액 | V2: 입금일 | W2: 공급처예금주
I3: 1658 | J3: 1566 | K3: 174 | L3: 835 | M3: 727 | N3: 35 | O3: 1597 | P3: 0 | S3: 1597 | T3: 12326800 | U3: 20901500 | V3: 0
Q4: ※ 주문서 작성시 KDG, 제이와이엠, 디피프로젝트 카톡 채널 공유 필수 | S4: 0 | T4: 0
T5: 0
A6: 리마인드 | B6: 경기도 고양시 일산동구 지영로 59-2 D동 | C6: 010-3918-2418 | D6: 010-9208-6514 | E6: S16809 | F6: 2420(부츠)sl (C) | G6: 베이지(기본M) | H6: 12000 | I6: 1 | L6: 1 | O6: 1 | S6: 1 | T6: 12000 | W6: （주）디투어패럴
A7: 리마인드 | B7: 경기도 고양시 일산동구 지영로 59-2 D동 | C7: 010-3918-2418 | D7: 010-9208-6514 | E7: S16836 | F7: 2420(부츠)sl (C) | G7: 블랙(기본M) | H7: 12000 | I7: 2 | L7: 2 | O7: 2 | S7: 2 | T7: 24000 | W7: （주）디투어패럴
A8: 리마인드 | B8: 경기도 고양시 일산동구 지영로 59-2 D동 | C8: 010-3918-2418 | D8: 010-9208-6514 | E8: S16838 | F8: 2420(부츠)sl (C) | G8: 블랙(롱S) | H8: 12000 | I8: 2 | L8: 2 | O8: 2 | S8: 2 | T8: 24000 | W8: （주）디투어패럴
A9: 리마인드 | B9: 경기도 고양시 일산동구 지영로 59-2 D동 | C9: 010-3918-2418 | D9: 010-9208-6514 | E9: S16800 | F9: 2420(부츠)sl (C) | G9: 아이보리(기본M) | H9: 12000 | I9: 1 | L9: 1 | O9: 1 | S9: 1 | T9: 12000 | W9: （주）디투어패럴
A10: 리마인드 | B10: 경기도 고양시 일산동구 지영로 59-2 D동 | C10: 010-3918-2418 | D10: 010-9208-6514 | E10: S16799 | F10: 2420(부츠)sl (C) | G10: 아이보리(기본S) | H10: 12000 | I10: 1 | L10: 1 | O10: 1 | S10: 1 | T10: 12000 | W10: （주）디투어패럴
A11: 리마인드 | B11: 경기도 고양시 일산동구 지영로 59-2 D동 | C11: 010-3918-2418 | D11: 010-9208-6514 | E11: S22135 | F11: 4503 [반바지] | G11: 베이지/L | H11: 10000 | I11: 2 | L11: 2 | O11: 2 | S11: 2 | T11: 20000 | W11: （주）디투어패럴
A12: 리마인드 | B12: 경기도 고양시 일산동구 지영로 59-2 D동 | C12: 010-3918-2418 | D12: 010-9208-6514 | E12: S22138 | F12: 4503 [반바지] | G12: 블랙/L | H12: 10000 | I12: 3 | L12: 3 | O12: 3 | S12: 3 | T12: 30000 | W12: （주）디투어패럴
A13: 리마인드 | B13: 경기도 고양시 일산동구 지영로 59-2 D동 | C13: 010-3918-2418 | D13: 010-9208-6514 | E13: S18814 | F13: 5007pt [부츠컷] | G13: 중청(L) | H13: 15000 | I13: 1 | L13: 1 | O13: 1 | S13: 1 | T13: 15000 | W13: （주）디투어패럴
A14: 리마인드 | B14: 경기도 고양시 일산동구 지영로 59-2 D동 | C14: 010-3918-2418 | D14: 010-9208-6514 | E14: S19667 | F14: 5100-3pt [부츠컷] | G14: 연청/L | H14: 14000 | I14: 2 | L14: 2 | O14: 2 | S14: 2 | T14: 28000 | W14: （주）디투어패럴
A15: 리마인드 | B15: 경기도 고양시 일산동구 지영로 59-2 D동 | C15: 010-3918-2418 | D15: 010-9208-6514 | E15: S19666 | F15: 5100-3pt [부츠컷] | G15: 연청/M | H15: 14000 | I15: 1 | L15: 1 | O15: 1 | S15: 1 | T15: 14000 | W15: （주）디투어패럴
A16: 리마인드 | B16: 경기도 고양시 일산동구 지영로 59-2 D동 | C16: 010-3918-2418 | D16: 010-9208-6514 | E16: S19665 | F16: 5100-3pt [부츠컷] | G16: 연청/S | H16: 14000 | I16: 1 | L16: 1 | O16: 1 | S16: 1 | T16: 14000 | W16: （주）디투어패럴
